Workbook

Sheet Hướng Dẫn
A1: HƯỚNG DẪN SỬ DỤNG PIPELINE PHUN XĂM VIC
A3: A. KHỞI ĐỘNG
A4: • File đã ở định dạng Google Sheets native (icon xanh). Mọi formula chạy được ngay.
A5: • Nếu mở từ Drive thấy icon "X" (Excel mode): File → Save as Google Sheets.
A7: B. QUY TRÌNH
A8: 1. NHÂN VIÊN nhập lead: vào sheet tên mình → mỗi inbox 1 dòng → chỉ điền ô màu XANH.
A9: • Dropdown bấm ▼ chọn trực tiếp. • Ô VÀNG (D, K) là auto — không sửa.
A10: • Thứ tự: Ngày Lead → Mã vùng → Số ĐT → các trường khác.
A11: 2. Paste KiotViet: vào sheet KiotViet → ô A2 → Ctrl+V (kể cả header cũng OK).
A12: • CSV của bạn có 13 cột → paste sẽ chiếm A:M. • CỘT N là vùng AUTO — không paste đè.
A13: 3. Master tự cập nhật. Đó là sheet đầu ra cuối cùng.
A15: C. SỨC CHỨA HIỆN TẠI
... A30: Muốn xem: View → Show hidden sheets.

Sheet Master
A1: SĐT Cuối | B1: Ngày Lead | C1: Thời gian (HĐ) | D1: CHATPAGE | E1: LOẠI TIN NHẮN | F1: NHÓM SP | G1: NGUỒN | H1: QUAN TÂM | I1: TÌNH TRẠNG | J1: Mã hóa đơn | K1: Mã khách hàng | L1: Tên hàng | M1: Doanh Thu (VNĐ) | N1: NGÀY HẸN | O1: Thời gian ra đơn (Ngày) | P1: Phễu | Q1: NHÓM SP_Clean | R1: Kênh Tiếp Cận | S1: Phân loại sản phẩm | T1: [F] 1_Có Inbox | U1: [F] 2_Có SĐT | V1: [F] 3_Có Đặt Lịch | W1: [F] 4_Có Ra Đơn | X1: Phân nhóm MECE | Y1: Lead_Unique_Flag | Z1: HĐ_Unique_Flag
A2: =IFERROR(__xludf.DUMMYFUNCTION("QUERY({'_KV_Block'!A2:X1501;'_Orphan_Block'!A2:X2501},""select * where Col1 is not null and Col1 <> ''"",0)"),"0389557477") -> 0389557477 | B2: =IFERROR(__xludf.DUMMYFUNCTION("""COMPUTED_VALUE"""),46023.0) -> 46023 | C2: =IFERROR(__xludf.DUMMYFUNCTION("""COMPUTED_VALUE"""),46026.0) -> 46026 | D2: =IFERROR(__xludf.DUMMYFUNCTION("""COMPUTED_VALUE"""),"Đặng Đông") -> Đặng Đông | E2: =IFERROR(__xludf.DUMMYFUNCTION("""COMPUTED_VALUE"""),"TỰ NHIÊN") -> TỰ NHIÊN | F2: =IFERROR(__xludf.DUMMYFUNCTION("""COMPUTED_VALUE"""),"DỊCH VỤ") -> DỊCH VỤ | G2: =IFERROR(__xludf.DUMMYFUNCTION("""COMPUTED_VALUE"""),"Fanpage PXV") -> Fanpage PXV | H2: =IFERROR(__xludf.DUMMYFUNCTION("""COMPUTED_VALUE"""),"Xoá mày") -> Xoá mày | I2: =IFERROR(__xludf.DUMMYFUNCTION("""COMPUTED_VALUE"""),"Nhắn Qua Zalo") -> Nhắn Qua Zalo | J2: =IFERROR(__xludf.DUMMYFUNCTION("""COMPUTED_VALUE"""),"HD028001") -> HD028001 | K2: =IFERROR(__xludf.DUMMYFUNCTION("""COMPUTED_VALUE"""),"KH004211") -> KH004211 | L2: =IFERROR(__xludf.DUMMYFUNCTION("""COMPUTED_VALUE"""),"(DV) Tạo sợi tả thực [NỮ] - DIAMOND") -> (DV) Tạo sợi tả thực [NỮ] - DIAMOND | M2: =IFERROR(__xludf.DUMMYFUNCTION("""COMPUTED_VALUE"""),9420000.0) -> 9420000 | N2: =IFERROR(__xludf.DUMMYFUNCTION("""COMPUTED_VALUE"""),46055.0) -> 46055 | O2: =IFERROR(__xludf.DUMMYFUNCTION("""COMPUTED_VALUE"""),3.452165428243461) -> 3.4521654 | P2: =IFERROR(__xludf.DUMMYFUNCTION("""COMPUTED_VALUE"""),FALSE) -> FALSE | Q2: =IFERROR(__xludf.DUMMYFUNCTION("""COMPUTED_VALUE"""),"DỊCH VỤ") -> DỊCH VỤ | R2: =IFERROR(__xludf.DUMMYFUNCTION("""COMPUTED_VALUE"""),"Facebook") -> Facebook | S2: =IFERROR(__xludf.DUMMYFUNCTION("""COMPUTED_VALUE"""),"Làm Mày") -> Làm Mày | T2: =IFERROR(__xludf.DUMMYFUNCTION("""COMPUTED_VALUE"""),1.0) -> 1 | U2: =IFERROR(__xludf.DUMMYFUNCTION("""COMPUTED_VALUE"""),1.0) -> 1 | V2: =IFERROR(__xludf.DUMMYFUNCTION("""COMPUTED_VALUE"""),1.0) -> 1 | W2: =IFERROR(__xludf.DUMMYFUNCTION("""COMPUTED_VALUE"""),1.0) -> 1 | X2: =IFERROR(__xludf.DUMMYFUNCTION("""COMPUTED_VALUE"""),"Nhóm 5: Lead hoàn hảo (Đủ 3 bước)") -> Nhóm 5: Lead hoàn hảo (Đủ 3 bước)
A3: =IFERROR(__xludf.DUMMYFUNCTION("""COMPUTED_VALUE"""),"0988887727") -> 0988887727 | C3: =IFERROR(__xludf.DUMMYFUNCTION("""COMPUTED_VALUE"""),46026.0) -> 46026 | J3: =IFERROR(__xludf.DUMMYFUNCTION("""COMPUTED_VALUE"""),"HD028004") -> HD028004 | K3: =IFERROR(__xludf.DUMMYFUNCTION("""COMPUTED_VALUE"""),"KH009044") -> KH009044 | L3: =IFERROR(__xludf.DUMMYFUNCTION("""COMPUTED_VALUE"""),"(DV) GÓI TIẾT KIỆM - XÓA CHÂN MÀY TRỌN GÓI") -> (DV) GÓI TIẾT KIỆM - XÓA CHÂN MÀY TRỌN GÓI | M3: =IFERROR(__xludf.DUMMYFUNCTION("""COMPUTED_VALUE"""),900000.0) -> 900000 | P3: =IFERROR(__xludf.DUMMYFUNCTION("""COMPUTED_VALUE"""),TRUE) -> TRUE | Q3: =IFERROR(__xludf.DUMMYFUNCTION("""COMPUTED_VALUE"""),"DỊCH VỤ") -> DỊCH VỤ | R3: =IFERROR(__xludf.DUMMYFUNCTION("""COMPUTED_VALUE"""),"Vãng lai") -> Vãng lai | S3: =IFERROR(__xludf.DUMMYFUNCTION("""COMPUTED_VALUE"""),"Xóa Laser") -> Xóa Laser | T3: =IFERROR(__xludf.DUMMYFUNCTION("""COMPUTED_VALUE"""),0.0) -> 0 | U3: =IFERROR(__xludf.DUMMYFUNCTION("""COMPUTED_VALUE"""),1.0) -> 1 | V3: =IFERROR(__xludf.DUMMYFUNCTION("""COMPUTED_VALUE"""),0.0) -> 0 | W3: =IFERROR(__xludf.DUMMYFUNCTION("""COMPUTED_VALUE"""),1.0) -> 1 | X3: =IFERROR(__xludf.DUMMYFUNCTION("""COMPUTED_VALUE"""),"Nhóm 1: Khách tự nhiên vãng lai (Chỉ có HĐ)") -> Nhóm 1: Khách tự nhiên vãng lai (Chỉ có HĐ)
A4: =IFERROR(__xludf.DUMMYFUNCTION("""COMPUTED_VALUE"""),"0985868707") -> 0985868707 | C4: =IFERROR(__xludf.DUMMYFUNCTION("""COMPUTED_VALUE"""),46026.0) -> 46026 | J4: =IFERROR(__xludf.DUMMYFUNCTION("""COMPUTED_VALUE"""),"HD028006.01") -> HD028006.01 | K4: =IFERROR(__xludf.DUMMYFUNCTION("""COMPUTED_VALUE"""),"KH009045") -> KH009045 | L4: =IFERROR(__xludf.DUMMYFUNCTION("""COMPUTED_VALUE"""),"(DV) Phun Môi - CÔ HƯỜNG") -> (DV) Phun Môi - CÔ HƯỜNG | M4: =IFERROR(__xludf.DUMMYFUNCTION("""COMPUTED_VALUE"""),1.503E7) -> 15030000 | P4: =IFERROR(__xludf.DUMMYFUNCTION("""COMPUTED_VALUE"""),FALSE) -> FALSE | Q4: =IFERROR(__xludf.DUMMYFUNCTION("""COMPUTED_VALUE"""),"DỊCH VỤ") -> DỊCH VỤ | R4: =IFERROR(__xludf.DUMMYFUNCTION("""COMPUTED_VALUE"""),"Vãng lai") -> Vãng lai | S4: =IFERROR(__xludf.DUMMYFUNCTION("""COMPUTED_VALUE"""),"Làm Môi") -> Làm Môi | T4: =IFERROR(__xludf.DUMMYFUNCTION("""COMPUTED_VALUE"""),0.0) -> 0 | U4: =IFERROR(__xludf.DUMMYFUNCTION("""COMPUTED_VALUE"""),1.0) -> 1 | V4: =IFERROR(__xludf.DUMMYFUNCTION("""COMPUTED_VALUE"""),0.0) -> 0 | W4: =IFERROR(__xludf.DUMMYFUNCTION("""COMPUTED_VALUE"""),1.0) -> 1 | X4: =IFERROR(__xludf.DUMMYFUNCTION("""COMPUTED_VALUE"""),"Nhóm 1: Khách tự nhiên vãng lai (Chỉ có HĐ)") -> Nhóm 1: Khách tự nhiên vãng lai (Chỉ có HĐ)
A5: =IFERROR(__xludf.DUMMYFUNCTION("""COMPUTED_VALUE"""),"0988887727") -> 0988887727 | C5: =IFERROR(__xludf.DUMMYFUNCTION("""COMPUTED_VALUE"""),46026.0) -> 46026 | J5: =IFERROR(__xludf.DUMMYFUNCTION("""COMPUTED_VALUE"""),"HD028011") -> HD028011 | K5: =IFERROR(__xludf.DUMMYFUNCTION("""COMPUTED_VALUE"""),"KH009044") -> KH009044 | L5: =IFERROR(__xludf.DUMMYFUNCTION("""COMPUTED_VALUE"""),"(DV) Khử thâm + Phun môi - GOLD") -> (DV) Khử thâm + Phun môi - GOLD | M5: =IFERROR(__xludf.DUMMYFUNCTION("""COMPUTED_VALUE"""),3490000.0) -> 3490000 | P5: =IFERROR(__xludf.DUMMYFUNCTION("""COMPUTED_VALUE"""),FALSE) -> FALSE | Q5: =IFERROR(__xludf.DUMMYFUNCTION("""COMPUTED_VALUE"""),"DỊCH VỤ") -> DỊCH VỤ | R5: =IFERROR(__xludf.DUMMYFUNCTION("""COMPUTED_VALUE"""),"Vãng lai") -> Vãng lai | S5: =IFERROR(__xludf.DUMMYFUNCTION("""COMPUTED_VALUE"""),"Làm Môi") -> Làm Môi | T5: =IFERROR(__xludf.DUMMYFUNCTION("""COMPUTED_VALUE"""),0.0) -> 0 | U5: =IFERROR(__xludf.DUMMYFUNCTION("""COMPUTED_VALUE"""),1.0) -> 1 | V5: =IFERROR(__xludf.DUMMYFUNCTION("""COMPUTED_VALUE"""),0.0) -> 0 | W5: =IFERROR(__xludf.DUMMYFUNCTION("""COMPUTED_VALUE"""),1.0) -> 1 | X5: =IFERROR(__xludf.DUMMYFUNCTION("""COMPUTED_VALUE"""),"Nhóm 1: Khách tự nhiên vãng lai (Chỉ có HĐ)") -> Nhóm 1: Khách tự nhiên vãng lai (Chỉ có HĐ)
A6: =IFERROR(__xludf.DUMMYFUNCTION("""COMPUTED_VALUE"""),"0908436728") -> 0908436728 | C6: =IFERROR(__xludf.DUMMYFUNCTION("""COMPUTED_VALUE"""),46026.0) -> 46026 | J6: =IFERROR(__xludf.DUMMYFUNCTION("""COMPUTED_VALUE"""),"HD028012") -> HD028012 | K6: =IFERROR(__xludf.DUMMYFUNCTION("""COMPUTED_VALUE"""),"KH008410") -> KH008410 | L6: =IFERROR(__xludf.DUMMYFUNCTION("""COMPUTED_VALUE"""),"(DV) Tạo sợi tả thực [NỮ] - CÔ HƯỜNG") -> (DV) Tạo sợi tả thực [NỮ] - CÔ HƯỜNG | M6: =IFERROR(__xludf.DUMMYFUNCTION("""COMPUTED_VALUE"""),1.797E7) -> 17970000 | P6: =IFERROR(__xludf.DUMMYFUNCTION("""COMPUTED_VALUE"""),FALSE) -> FALSE | Q6: =IFERROR(__xludf.DUMMYFUNCTION("""COMPUTED_VALUE"""),"DỊCH VỤ") -> DỊCH VỤ | R6: =IFERROR(__xludf.DUMMYFUNCTION("""COMPUTED_VALUE"""),"Vãng lai") -> Vãng lai | S6: =IFERROR(__xludf.DUMMYFUNCTION("""COMPUTED_VALUE"""),"Làm Mày") -> Làm Mày | T6: =IFERROR(__xludf.DUMMYFUNCTION("""COMPUTED_VALUE"""),0.0) -> 0 | U6: =IFERROR(__xludf.DUMMYFUNCTION("""COMPUTED_VALUE"""),1.0) -> 1 | V6: =IFERROR(__xludf.DUMMYFUNCTION("""COMPUTED_VALUE"""),0.0) -> 0 | W6: =IFERROR(__xludf.DUMMYFUNCTION("""COMPUTED_VALUE"""),1.0) -> 1 | X6: =IFERROR(__xludf.DUMMYFUNCTION("""COMPUTED_VALUE"""),"Nhóm 1: Khách tự nhiên vãng lai (Chỉ có HĐ)") -> Nhóm 1: Khách tự nhiên vãng lai (Chỉ có HĐ)
A7: =IFERROR(__xludf.DUMMYFUNCTION("""COMPUTED_VALUE"""),"0565867163") -> 0565867163 | C7: =IFERROR(__xludf.DUMMYFUNCTION("""COMPUTED_VALUE"""),46026.0) -> 46026 | J7: =IFERROR(__xludf.DUMMYFUNCTION("""COMPUTED_VALUE"""),"HD028013") -> HD028013 | K7: =IFERROR(__xludf.DUMMYFUNCTION("""COMPUTED_VALUE"""),"KH009046") -> KH009046 | L7: =IFERROR(__xludf.DUMMYFUNCTION("""COMPUTED_VALUE"""),"(DV) GÓI TIẾT KIỆM - XÓA CHÂN MÀY TRỌN GÓI") -> (DV) GÓI TIẾT KIỆM - XÓA CHÂN MÀY TRỌN GÓI | M7: =IFERROR(__xludf.DUMMYFUNCTION("""COMPUTED_VALUE"""),900000.0) -> 900000 | P7: =IFERROR(__xludf.DUMMYFUNCTION("""COMPUTED_VALUE"""),TRUE) -> TRUE | Q7: =IFERROR(__xludf.DUMMYFUNCTION("""COMPUTED_VALUE"""),"DỊCH VỤ") -> DỊCH VỤ | R7: =IFERROR(__xludf.DUMMYFUNCTION("""COMPUTED_VALUE"""),"Vãng lai") -> Vãng lai | S7: =IFERROR(__xludf.DUMMYFUNCTION("""COMPUTED_VALUE"""),"Xóa Laser") -> Xóa Laser | T7: =IFERROR(__xludf.DUMMYFUNCTION("""COMPUTED_VALUE"""),0.0) -> 0 | U7: =IFERROR(__xludf.DUMMYFUNCTION("""COMPUTED_VALUE"""),1.0) -> 1 | V7: =IFERROR(__xludf.DUMMYFUNCTION("""COMPUTED_VALUE"""),0.0) -> 0 | W7: =IFERROR(__xludf.DUMMYFUNCTION("""COMPUTED_VALUE"""),1.0) -> 1 | X7: =IFERROR(__xludf.DUMMYFUNCTION("""COMPUTED_VALUE"""),"Nhóm 1: Khách tự nhiên vãng lai (Chỉ có HĐ)") -> Nhóm 1: Khách tự nhiên vãng lai (Chỉ có HĐ)
A8: =IFERROR(__xludf.DUMMYFUNCTION("""COMPUTED_VALUE"""),"0974992869") -> 0974992869 | C8: =IFERROR(__xludf.DUMMYFUNCTION("""COMPUTED_VALUE"""),46026.0) -> 46026 | J8: =IFERROR(__xludf.DUMMYFUNCTION("""COMPUTED_VALUE"""),"HD028014") -> HD028014 | K8: =IFERROR(__xludf.DUMMYFUNCTION("""COMPUTED_VALUE"""),"KH008349") -> KH008349 | L8: =IFERROR(__xludf.DUMMYFUNCTION("""COMPUTED_VALUE"""),"(DV) Double bóc tách - GOLD") -> (DV) Double bóc tách - GOLD | M8: =IFERROR(__xludf.DUMMYFUNCTION("""COMPUTED_VALUE"""),2700000.0) -> 2700000 | P8: =IFERROR(__xludf.DUMMYFUNCTION("""COMPUTED_VALUE"""),FALSE) -> FALSE | Q8: =IFERROR(__xludf.DUMMYFUNCTION("""COMPUTED_VALUE"""),"DỊCH VỤ") -> DỊCH VỤ | R8: =IFERROR(__xludf.DUMMYFUNCTION("""COMPUTED_VALUE"""),"Vãng lai") -> Vãng lai | S8: =IFERROR(__xludf.DUMMYFUNCTION("""COMPUTED_VALUE"""),"CO2 / Cắt đáy sẹo") -> CO2 / Cắt đáy sẹo | T8: =IFERROR(__xludf.DUMMYFUNCTION("""COMPUTED_VALUE"""),0.0) -> 0 | U8: =IFERROR(__xludf.DUMMYFUNCTION("""COMPUTED_VALUE"""),1.0) -> 1 | V8: =IFERROR(__xludf.DUMMYFUNCTION("""COMPUTED_VALUE"""),0.0) -> 0 | W8: =IFERROR(__xludf.DUMMYFUNCTION("""COMPUTED_VALUE"""),1.0) -> 1 | X8: =IFERROR(__xludf.DUMMYFUNCTION("""COMPUTED_VALUE"""),"Nhóm 1: Khách tự nhiên vãng lai (Chỉ có HĐ)") -> Nhóm 1: Khách tự nhiên vãng lai (Chỉ có HĐ)
A9: =IFERROR(__xludf.DUMMYFUNCTION("""COMPUTED_VALUE"""),"0896146217") -> 0896146217 | C9: =IFERROR(__xludf.DUMMYFUNCTION("""COMPUTED_VALUE"""),46026.0) -> 46026 | J9: =IFERROR(__xludf.DUMMYFUNCTION("""COMPUTED_VALUE"""),"HD028016") -> HD028016 | K9: =IFERROR(__xludf.DUMMYFUNCTION("""COMPUTED_VALUE"""),"KH009043") -> KH009043 | L9: =IFERROR(__xludf.DUMMYFUNCTION("""COMPUTED_VALUE"""),"(DV) Tạo sợi tả thực [NỮ] - DIAMOND") -> (DV) Tạo sợi tả thực [NỮ] - DIAMOND | M9: =IFERROR(__xludf.DUMMYFUNCTION("""COMPUTED_VALUE"""),1.08E7) -> 10800000 | P9: =IFERROR(__xludf.DUMMYFUNCTION("""COMPUTED_VALUE"""),FALSE) -> FALSE | Q9: =IFERROR(__xludf.DUMMYFUNCTION("""COMPUTED_VALUE"""),"DỊCH VỤ") -> DỊCH VỤ | R9: =IFERROR(__xludf.DUMMYFUNCTION("""COMPUTED_VALUE"""),"Vãng lai") -> Vãng lai | S9: =IFERROR(__xludf.DUMMYFUNCTION("""COMPUTED_VALUE"""),"Làm Mày") -> Làm Mày | T9: =IFERROR(__xludf.DUMMYFUNCTION("""COMPUTED_VALUE"""),0.0) -> 0 | U9: =IFERROR(__xludf.DUMMYFUNCTION("""COMPUTED_VALUE"""),1.0) -> 1 | V9: =IFERROR(__xludf.DUMMYFUNCTION("""COMPUTED_VALUE"""),0.0) -> 0 | W9: =IFERROR(__xludf.DUMMYFUNCTION("""COMPUTED_VALUE"""),1.0) -> 1 | X9: =IFERROR(__xludf.DUMMYFUNCTION("""COMPUTED_VALUE"""),"Nhóm 1: Khách tự nhiên vãng lai (Chỉ có HĐ)") -> Nhóm 1: Khách tự nhiên vãng lai (Chỉ có HĐ)
A10: =IFERROR(__xludf.DUMMYFUNCTION("""COMPUTED_VALUE"""),"0896146217") -> 0896146217 | C10: =IFERROR(__xludf.DUMMYFUNCTION("""COMPUTED_VALUE"""),46026.0) -> 46026 | J10: =IFERROR(__xludf.DUMMYFUNCTION("""COMPUTED_VALUE"""),"HD028017") -> HD028017 | K10: =IFERROR(__xludf.DUMMYFUNCTION("""COMPUTED_VALUE"""),"KH009043") -> KH009043 | L10: =IFERROR(__xludf.DUMMYFUNCTION("""COMPUTED_VALUE"""),"(DV) Double bóc tách - DIAMOND") -> (DV) Double bóc tách - DIAMOND | M10: =IFERROR(__xludf.DUMMYFUNCTION("""COMPUTED_VALUE"""),8100000.0) -> 8100000 | P10: =IFERROR(__xludf.DUMMYFUNCTION("""COMPUTED_VALUE"""),FALSE) -> FALSE | Q10: =IFERROR(__xludf.DUMMYFUNCTION("""COMPUTED_VALUE"""),"DỊCH VỤ") -> DỊCH VỤ | R10: =IFERROR(__xludf.DUMMYFUNCTION("""COMPUTED_VALUE"""),"Vãng lai") -> Vãng lai | S10: =IFERROR(__xludf.DUMMYFUNCTION("""COMPUTED_VALUE"""),"CO2 / Cắt đáy sẹo") -> CO2 / Cắt đáy sẹo | T10: =IFERROR(__xludf.DUMMYFUNCTION("""COMPUTED_VALUE"""),0.0) -> 0 | U10: =IFERROR(__xludf.DUMMYFUNCTION("""COMPUTED_VALUE"""),1.0) -> 1 | V10: =IFERROR(__xludf.DUMMYFUNCTION("""COMPUTED_VALUE"""),0.0) -> 0 | W10: =IFERROR(__xludf.DUMMYFUNCTION("""COMPUTED_VALUE"""),1.0) -> 1 | X10: =IFERROR(__xludf.DUMMYFUNCTION("""COMPUTED_VALUE"""),"Nhóm 1: Khách tự nhiên vãng lai (Chỉ có HĐ)") -> Nhóm 1: Khách tự nhiên vãng lai (Chỉ có HĐ)
A11: =IFERROR(__xludf.DUMMYFUNCTION("""COMPUTED_VALUE"""),"0909616797") -> 0909616797 | C11: =IFERROR(__xludf.DUMMYFUNCTION("""COMPUTED_VALUE"""),46026.0) -> 46026 | J11: =IFERROR(__xludf.DUMMYFUNCTION("""COMPUTED_VALUE"""),"HD028018") -> HD028018 | K11: =IFERROR(__xludf.DUMMYFUNCTION("""COMPUTED_VALUE"""),"KH009047") -> KH009047 | L11: =IFERROR(__xludf.DUMMYFUNCTION("""COMPUTED_VALUE"""),"(DV) GÓI TIẾT KIỆM - XÓA CHÂN MÀY TRỌN GÓI") -> (DV) GÓI TIẾT KIỆM - XÓA CHÂN MÀY TRỌN GÓI | M11: =IFERROR(__xludf.DUMMYFUNCTION("""COMPUTED_VALUE"""),900000.0) -> 900000 | P11: =IFERROR(__xludf.DUMMYFUNCTION("""COMPUTED_VALUE"""),TRUE) -> TRUE | Q11: =IFERROR(__xludf.DUMMYFUNCTION("""COMPUTED_VALUE"""),"DỊCH VỤ") -> DỊCH VỤ | R11: =IFERROR(__xludf.DUMMYFUNCTION("""COMPUTED_VALUE"""),"Vãng lai") -> Vãng lai | S11: =IFERROR(__xludf.DUMMYFUNCTION("""COMPUTED_VALUE"""),"Xóa Laser") -> Xóa Laser | T11: =IFERROR(__xludf.DUMMYFUNCTION("""COMPUTED_VALUE"""),0.0) -> 0 | U11: =IFERROR(__xludf.DUMMYFUNCTION("""COMPUTED_VALUE"""),1.0) -> 1 | V11: =IFERROR(__xludf.DUMMYFUNCTION("""COMPUTED_VALUE"""),0.0) -> 0 | W11: =IFERROR(__xludf.DUMMYFUNCTION("""COMPUTED_VALUE"""),1.0) -> 1 | X11: =IFERROR(__xludf.DUMMYFUNCTION("""COMPUTED_VALUE"""),"Nhóm 1: Khách tự nhiên vãng lai (Chỉ có HĐ)") -> Nhóm 1: Khách tự nhiên vãng lai (Chỉ có HĐ)
A12: =IFERROR(__xludf.DUMMYFUNCTION("""COMPUTED_VALUE"""),"0909616797") -> 0909616797 | C12: =IFERROR(__xludf.DUMMYFUNCTION("""COMPUTED_VALUE"""),46026.0) -> 46026 | J12: =IFERROR(__xludf.DUMMYFUNCTION("""COMPUTED_VALUE"""),"HD028019") -> HD028019 | K12: =IFERROR(__xludf.DUMMYFUNCTION("""COMPUTED_VALUE"""),"KH009047") -> KH009047 | L12: =IFERROR(__xludf.DUMMYFUNCTION("""COMPUTED_VALUE"""),"(DV) Công nghệ CO2 Fractional - Tách thâm") -> (DV) Công nghệ CO2 Fractional - Tách thâm | M12: =IFERROR(__xludf.DUMMYFUNCTION("""COMPUTED_VALUE"""),1490000.0) -> 1490000 | P12: =IFERROR(__xludf.DUMMYFUNCTION("""COMPUTED_VALUE"""),TRUE) -> TRUE | Q12: =IFERROR(__xludf.DUMMYFUNCTION("""COMPUTED_VALUE"""),"DỊCH VỤ") -> DỊCH VỤ | R12: =IFERROR(__xludf.DUMMYFUNCTION("""COMPUTED_VALUE"""),"Vãng lai") -> Vãng lai | S12: =IFERROR(__xludf.DUMMYFUNCTION("""COMPUTED_VALUE"""),"CO2 / Cắt đáy sẹo") -> CO2 / Cắt đáy sẹo | T12: =IFERROR(__xludf.DUMMYFUNCTION("""COMPUTED_VALUE"""),0.0) -> 0 | U12: =IFERROR(__xludf.DUMMYFUNCTION("""COMPUTED_VALUE"""),1.0) -> 1 | V12: =IFERROR(__xludf.DUMMYFUNCTION("""COMPUTED_VALUE"""),0.0) -> 0 | W12: =IFERROR(__xludf.DUMMYFUNCTION("""COMPUTED_VALUE"""),1.0) -> 1 | X12: =IFERROR(__xludf.DUMMYFUNCTION("""COMPUTED_VALUE"""),"Nhóm 1: Khách tự nhiên vãng lai (Chỉ có HĐ)") -> Nhóm 1: Khách tự nhiên vãng lai (Chỉ có HĐ)
A13: =IFERROR(__xludf.DUMMYFUNCTION("""COMPUTED_VALUE"""),"0939431555") -> 0939431555 | C13: =IFERROR(__xludf.DUMMYFUNCTION("""COMPUTED_VALUE"""),46026.0) -> 46026 | J13: =IFERROR(__xludf.DUMMYFUNCTION("""COMPUTED_VALUE"""),"HD028020") -> HD028020 | K13: =IFERROR(__xludf.DUMMYFUNCTION("""COMPUTED_VALUE"""),"KH009048") -> KH009048 | L13: =IFERROR(__xludf.DUMMYFUNCTION("""COMPUTED_VALUE"""),"(DV) Xử lý nền + Phun môi - PLATINUM") -> (DV) Xử lý nền + Phun môi - PLATINUM | M13: =IFERROR(__xludf.DUMMYFUNCTION("""COMPUTED_VALUE"""),6600000.0) -> 6600000 | P13: =IFERROR(__xludf.DUMMYFUNCTION("""COMPUTED_VALUE"""),FALSE) -> FALSE | Q13: =IFERROR(__xludf.DUMMYFUNCTION("""COMPUTED_VALUE"""),"DỊCH VỤ") -> DỊCH VỤ | R13: =IFERROR(__xludf.DUMMYFUNCTION("""COMPUTED_VALUE"""),"Vãng lai") -> Vãng lai | S13: =IFERROR(__xludf.DUMMYFUNCTION("""COMPUTED_VALUE"""),"Làm Môi") -> Làm Môi | T13: =IFERROR(__xludf.DUMMYFUNCTION("""COMPUTED_VALUE"""),0.0) -> 0 | U13: =IFERROR(__xludf.DUMMYFUNCTION("""COMPUTED_VALUE"""),1.0) -> 1 | V13: =IFERROR(__xludf.DUMMYFUNCTION("""COMPUTED_VALUE"""),0.0) -> 0 | W13: =IFERROR(__xludf.DUMMYFUNCTION("""COMPUTED_VALUE"""),1.0) -> 1 | X13: =IFERROR(__xludf.DUMMYFUNCTION("""COMPUTED_VALUE"""),"Nhóm 1: Khách tự nhiên vãng lai (Chỉ có HĐ)") -> Nhóm 1: Khách tự nhiên vãng lai (Chỉ có HĐ)
A14: =IFERROR(__xludf.DUMMYFUNCTION("""COMPUTED_VALUE"""),"0989413672") -> 0989413672 | C14: =IFERROR(__xludf.DUMMYFUNCTION("""COMPUTED_VALUE"""),46026.0) -> 46026 | J14: =IFERROR(__xludf.DUMMYFUNCTION("""COMPUTED_VALUE"""),"HD028021") -> HD028021 | K14: =IFERROR(__xludf.DUMMYFUNCTION("""COMPUTED_VALUE"""),"KH009049") -> KH009049 | L14: =IFERROR(__xludf.DUMMYFUNCTION("""COMPUTED_VALUE"""),"(DV) GÓI TIẾT KIỆM - XÓA CHÂN MÀY TRỌN GÓI") -> (DV) GÓI TIẾT KIỆM - XÓA CHÂN MÀY TRỌN GÓI | M14: =IFERROR(__xludf.DUMMYFUNCTION("""COMPUTED_VALUE"""),900000.0) -> 900000 | P14: =IFERROR(__xludf.DUMMYFUNCTION("""COMPUTED_VALUE"""),TRUE) -> TRUE | Q14: =IFERROR(__xludf.DUMMYFUNCTION("""COMPUTED_VALUE"""),"DỊCH VỤ") -> DỊCH VỤ | R14: =IFERROR(__xludf.DUMMYFUNCTION("""COMPUTED_VALUE"""),"Vãng lai") -> Vãng lai | S14: =IFERROR(__xludf.DUMMYFUNCTION("""COMPUTED_VALUE"""),"Xóa Laser") -> Xóa Laser | T14: =IFERROR(__xludf.DUMMYFUNCTION("""COMPUTED_VALUE"""),0.0) -> 0 | U14: =IFERROR(__xludf.DUMMYFUNCTION("""COMPUTED_VALUE"""),1.0) -> 1 | V14: =IFERROR(__xludf.DUMMYFUNCTION("""COMPUTED_VALUE"""),0.0) -> 0 | W14: =IFERROR(__xludf.DUMMYFUNCTION("""COMPUTED_VALUE"""),1.0) -> 1 | X14: =IFERROR(__xludf.DUMMYFUNCTION("""COMPUTED_VALUE"""),"Nhóm 1: Khách tự nhiên vãng lai (Chỉ có HĐ)") -> Nhóm 1: Khách tự nhiên vãng lai (Chỉ có HĐ)
A15: =IFERROR(__xludf.DUMMYFUNCTION("""COMPUTED_VALUE"""),"0944704036") -> 0944704036 | C15: =IFERROR(__xludf.DUMMYFUNCTION("""COMPUTED_VALUE"""),46026.0) -> 46026 | J15: =IFERROR(__xludf.DUMMYFUNCTION("""COMPUTED_VALUE"""),"HD028022") -> HD028022 | K15: =IFERROR(__xludf.DUMMYFUNCTION("""COMPUTED_VALUE"""),"KH009050") -> KH009050 | L15: =IFERROR(__xludf.DUMMYFUNCTION("""COMPUTED_VALUE"""),"(DV) Xóa lần 01 - Chân Mày") -> (DV) Xóa lần 01 - Chân Mày | M15: =IFERROR(__xludf.DUMMYFUNCTION("""COMPUTED_VALUE"""),900000.0) -> 900000 | P15: =IFERROR(__xludf.DUMMYFUNCTION("""COMPUTED_VALUE"""),TRUE) -> TRUE | Q15: =IFERROR(__xludf.DUMMYFUNCTION("""COMPUTED_VALUE"""),"DỊCH VỤ") -> DỊCH VỤ | R15: =IFERROR(__xludf.DUMMYFUNCTION("""COMPUTED_VALUE"""),"Vãng lai") -> Vãng lai | S15: =IFERROR(__xludf.DUMMYFUNCTION("""COMPUTED_VALUE"""),"Xóa Laser") -> Xóa Laser | T15: =IFERROR(__xludf.DUMMYFUNCTION("""COMPUTED_VALUE"""),0.0) -> 0 | U15: =IFERROR(__xludf.DUMMYFUNCTION("""COMPUTED_VALUE"""),1.0) -> 1 | V15: =IFERROR(__xludf.DUMMYFUNCTION("""COMPUTED_VALUE"""),0.0) -> 0 | W15: =IFERROR(__xludf.DUMMYFUNCTION("""COMPUTED_VALUE"""),1.0) -> 1 | X15: =IFERROR(__xludf.DUMMYFUNCTION("""COMPUTED_VALUE"""),"Nhóm 1: Khách tự nhiên vãng lai (Chỉ có HĐ)") -> Nhóm 1: Khách tự nhiên vãng lai (Chỉ có HĐ)
A16: =IFERROR(__xludf.DUMMYFUNCTION("""COMPUTED_VALUE"""),"0896146217") -> 0896146217 | C16: =IFERROR(__xludf.DUMMYFUNCTION("""COMPUTED_VALUE"""),46026.0) -> 46026 | J16: =IFERROR(__xludf.DUMMYFUNCTION("""COMPUTED_VALUE"""),"HD028023") -> HD028023 | K16: =IFERROR(__xludf.DUMMYFUNCTION("""COMPUTED_VALUE"""),"KH009043") -> KH009043 | L16: =IFERROR(__xludf.DUMMYFUNCTION("""COMPUTED_VALUE"""),"(DV) Tạo sợi tả thực [NAM] - DIAMOND") -> (DV) Tạo sợi tả thực [NAM] - DIAMOND | M16: =IFERROR(__xludf.DUMMYFUNCTION("""COMPUTED_VALUE"""),1.13E7) -> 11300000 | P16: =IFERROR(__xludf.DUMMYFUNCTION("""COMPUTED_VALUE"""),FALSE) -> FALSE | Q16: =IFERROR(__xludf.DUMMYFUNCTION("""COMPUTED_VALUE"""),"DỊCH VỤ") -> DỊCH VỤ | R16: =IFERROR(__xludf.DUMMYFUNCTION("""COMPUTED_VALUE"""),"Vãng lai") -> Vãng lai | S16: =IFERROR(__xludf.DUMMYFUNCTION("""COMPUTED_VALUE"""),"Làm Mày") -> Làm Mày | T16: =IFERROR(__xludf.DUMMYFUNCTION("""COMPUTED_VALUE"""),0.0) -> 0 | U16: =IFERROR(__xludf.DUMMYFUNCTION("""COMPUTED_VALUE"""),1.0) -> 1 | V16: =IFERROR(__xludf.DUMMYFUNCTION("""COMPUTED_VALUE"""),0.0) -> 0 | W16: =IFERROR(__xludf.DUMMYFUNCTION("""COMPUTED_VALUE"""),1.0) -> 1 | X16: =IFERROR(__xludf.DUMMYFUNCTION("""COMPUTED_VALUE"""),"Nhóm 1: Khách tự nhiên vãng lai (Chỉ có HĐ)") -> Nhóm 1: Khách tự nhiên vãng lai (Chỉ có HĐ)
A17: =IFERROR(__xludf.DUMMYFUNCTION("""COMPUTED_VALUE"""),"0783316640") -> 0783316640 | C17: =IFERROR(__xludf.DUMMYFUNCTION("""COMPUTED_VALUE"""),46027.0) -> 46027 | J17: =IFERROR(__xludf.DUMMYFUNCTION("""COMPUTED_VALUE"""),"HD028033") -> HD028033 | K17: =IFERROR(__xludf.DUMMYFUNCTION("""COMPUTED_VALUE"""),"KH009054") -> KH009054 | L17: =IFERROR(__xludf.DUMMYFUNCTION("""COMPUTED_VALUE"""),"(DV) Công nghệ CO2 Fractional - Tách thâm") -> (DV) Công nghệ CO2 Fractional - Tách thâm | M17: =IFERROR(__xludf.DUMMYFUNCTION("""COMPUTED_VALUE"""),1490000.0) -> 1490000 | P17: =IFERROR(__xludf.DUMMYFUNCTION("""COMPUTED_VALUE"""),TRUE) -> TRUE | Q17: =IFERROR(__xludf.DUMMYFUNCTION("""COMPUTED_VALUE"""),"DỊCH VỤ") -> DỊCH VỤ | R17: =IFERROR(__xludf.DUMMYFUNCTION("""COMPUTED_VALUE"""),"Vãng lai") -> Vãng lai | S17: =IFERROR(__xludf.DUMMYFUNCTION("""COMPUTED_VALUE"""),"CO2 / Cắt đáy sẹo") -> CO2 / Cắt đáy sẹo | T17: =IFERROR(__xludf.DUMMYFUNCTION("""COMPUTED_VALUE"""),0.0) -> 0 | U17: =IFERROR(__xludf.DUMMYFUNCTION("""COMPUTED_VALUE"""),1.0) -> 1 | V17: =IFERROR(__xludf.DUMMYFUNCTION("""COMPUTED_VALUE"""),0.0) -> 0 | W17: =IFERROR(__xludf.DUMMYFUNCTION("""COMPUTED_VALUE"""),1.0) -> 1 | X17: =IFERROR(__xludf.DUMMYFUNCTION("""COMPUTED_VALUE"""),"Nhóm 1: Khách tự nhiên vãng lai (Chỉ có HĐ)") -> Nhóm 1: Khách tự nhiên vãng lai (Chỉ có HĐ)
A18: =IFERROR(__xludf.DUMMYFUNCTION("""COMPUTED_VALUE"""),"0906528838") -> 0906528838 | C18: =IFERROR(__xludf.DUMMYFUNCTION("""COMPUTED_VALUE"""),46027.0) -> 46027 | J18: =IFERROR(__xludf.DUMMYFUNCTION("""COMPUTED_VALUE"""),"HD028035") -> HD028035 | K18: =IFERROR(__xludf.DUMMYFUNCTION("""COMPUTED_VALUE"""),"KH009056") -> KH009056 | L18: =IFERROR(__xludf.DUMMYFUNCTION("""COMPUTED_VALUE"""),"(DV) GÓI TIẾT KIỆM - XÓA CHÂN MÀY TRỌN GÓI") -> (DV) GÓI TIẾT KIỆM - XÓA CHÂN MÀY TRỌN GÓI | M18: =IFERROR(__xludf.DUMMYFUNCTION("""COMPUTED_VALUE"""),900000.0) -> 900000 | P18: =IFERROR(__xludf.DUMMYFUNCTION("""COMPUTED_VALUE"""),TRUE) -> TRUE | Q18: =IFERROR(__xludf.DUMMYFUNCTION("""COMPUTED_VALUE"""),"DỊCH VỤ") -> DỊCH VỤ | R18: =IFERROR(__xludf.DUMMYFUNCTION("""COMPUTED_VALUE"""),"Vãng lai") -> Vãng lai | S18: =IFERROR(__xludf.DUMMYFUNCTION("""COMPUTED_VALUE"""),"Xóa Laser") -> Xóa Laser | T18: =IFERROR(__xludf.DUMMYFUNCTION("""COMPUTED_VALUE"""),0.0) -> 0 | U18: =IFERROR(__xludf.DUMMYFUNCTION("""COMPUTED_VALUE"""),1.0) -> 1 | V18: =IFERROR(__xludf.DUMMYFUNCTION("""COMPUTED_VALUE"""),0.0) -> 0 | W18: =IFERROR(__xludf.DUMMYFUNCTION("""COMPUTED_VALUE"""),1.0) -> 1 | X18: =IFERROR(__xludf.DUMMYFUNCTION("""COMPUTED_VALUE"""),"Nhóm 1: Khách tự nhiên vãng lai (Chỉ có HĐ)") -> Nhóm 1: Khách tự nhiên vãng lai (Chỉ có HĐ)
A19: =IFERROR(__xludf.DUMMYFUNCTION("""COMPUTED_VALUE"""),"0932781732") -> 0932781732 | C19: =IFERROR(__xludf.DUMMYFUNCTION("""COMPUTED_VALUE"""),46027.0) -> 46027 | J19: =IFERROR(__xludf.DUMMYFUNCTION("""COMPUTED_VALUE"""),"HD028036") -> HD028036 | K19: =IFERROR(__xludf.DUMMYFUNCTION("""COMPUTED_VALUE"""),"KH008276") -> KH008276 | L19: =IFERROR(__xludf.DUMMYFUNCTION("""COMPUTED_VALUE"""),"(DV) Tạo sợi tả thực (NỮ) - GOLD") -> (DV) Tạo sợi tả thực (NỮ) - GOLD | M19: =IFERROR(__xludf.DUMMYFUNCTION("""COMPUTED_VALUE"""),3390000.0) -> 3390000 | P19: =IFERROR(__xludf.DUMMYFUNCTION("""COMPUTED_VALUE"""),FALSE) -> FALSE | Q19: =IFERROR(__xludf.DUMMYFUNCTION("""COMPUTED_VALUE"""),"DỊCH VỤ") -> DỊCH VỤ | R19: =IFERROR(__xludf.DUMMYFUNCTION("""COMPUTED_VALUE"""),"Vãng lai") -> Vãng lai | S19: =IFERROR(__xludf.DUMMYFUNCTION("""COMPUTED_VALUE"""),"Làm Mày") -> Làm Mày | T19: =IFERROR(__xludf.DUMMYFUNCTION("""COMPUTED_VALUE"""),0.0) -> 0 | U19: =IFERROR(__xludf.DUMMYFUNCTION("""COMPUTED_VALUE"""),1.0) -> 1 | V19: =IFERROR(__xludf.DUMMYFUNCTION("""COMPUTED_VALUE"""),0.0) -> 0 | W19: =IFERROR(__xludf.DUMMYFUNCTION("""COMPUTED_VALUE"""),1.0) -> 1 | X19: =IFERROR(__xludf.DUMMYFUNCTION("""COMPUTED_VALUE"""),"Nhóm 1: Khách tự nhiên vãng lai (Chỉ có HĐ)") -> Nhóm 1: Khách tự nhiên vãng lai (Chỉ có HĐ)
A20: =IFERROR(__xludf.DUMMYFUNCTION("""COMPUTED_VALUE"""),"0899462050") -> 0899462050 | C20: =IFERROR(__xludf.DUMMYFUNCTION("""COMPUTED_VALUE"""),46027.0) -> 46027 | J20: =IFERROR(__xludf.DUMMYFUNCTION("""COMPUTED_VALUE"""),"HD028037") -> HD028037 | K20: =IFERROR(__xludf.DUMMYFUNCTION("""COMPUTED_VALUE"""),"KH009051") -> KH009051 | L20: =IFERROR(__xludf.DUMMYFUNCTION("""COMPUTED_VALUE"""),"(DV) Double bóc tách - DIAMOND") -> (DV) Double bóc tách - DIAMOND | M20: =IFERROR(__xludf.DUMMYFUNCTION("""COMPUTED_VALUE"""),7100000.0) -> 7100000 | P20: =IFERROR(__xludf.DUMMYFUNCTION("""COMPUTED_VALUE"""),FALSE) -> FALSE | Q20: =IFERROR(__xludf.DUMMYFUNCTION("""COMPUTED_VALUE"""),"DỊCH VỤ") -> DỊCH VỤ | R20: =IFERROR(__xludf.DUMMYFUNCTION("""COMPUTED_VALUE"""),"Vãng lai") -> Vãng lai | S20: =IFERROR(__xludf.DUMMYFUNCTION("""COMPUTED_VALUE"""),"CO2 / Cắt đáy sẹo") -> CO2 / Cắt đáy sẹo | T20: =IFERROR(__xludf.DUMMYFUNCTION("""COMPUTED_VALUE"""),0.0) -> 0 | U20: =IFERROR(__xludf.DUMMYFUNCTION("""COMPUTED_VALUE"""),1.0) -> 1 | V20: =IFERROR(__xludf.DUMMYFUNCTION("""COMPUTED_VALUE"""),0.0) -> 0 | W20: =IFERROR(__xludf.DUMMYFUNCTION("""COMPUTED_VALUE"""),1.0) -> 1 | X20: =IFERROR(__xludf.DUMMYFUNCTION("""COMPUTED_VALUE"""),"Nhóm 1: Khách tự nhiên vãng lai (Chỉ có HĐ)") -> Nhóm 1: Khách tự nhiên vãng lai (Chỉ có HĐ)
A21: =IFERROR(__xludf.DUMMYFUNCTION("""COMPUTED_VALUE"""),"0909343459") -> 0909343459 | C21: =IFERROR(__xludf.DUMMYFUNCTION("""COMPUTED_VALUE"""),46027.0) -> 46027 | J21: =IFERROR(__xludf.DUMMYFUNCTION("""COMPUTED_VALUE"""),"HD028038") -> HD028038 | K21: =IFERROR(__xludf.DUMMYFUNCTION("""COMPUTED_VALUE"""),"KH009058") -> KH009058 | L21: =IFERROR(__xludf.DUMMYFUNCTION("""COMPUTED_VALUE"""),"(DV) GÓI TIẾT KIỆM - XÓA CHÂN MÀY TRỌN GÓI") -> (DV) GÓI TIẾT KIỆM - XÓA CHÂN MÀY TRỌN GÓI | M21: =IFERROR(__xludf.DUMMYFUNCTION("""COMPUTED_VALUE"""),0.0) -> 0 | P21: =IFERROR(__xludf.DUMMYFUNCTION("""COMPUTED_VALUE"""),TRUE) -> TRUE | Q21: =IFERROR(__xludf.DUMMYFUNCTION("""COMPUTED_VALUE"""),"DỊCH VỤ") -> DỊCH VỤ | R21: =IFERROR(__xludf.DUMMYFUNCTION("""COMPUTED_VALUE"""),"Vãng lai") -> Vãng lai | S21: =IFERROR(__xludf.DUMMYFUNCTION("""COMPUTED_VALUE"""),"Xóa Laser") -> Xóa Laser | T21: =IFERROR(__xludf.DUMMYFUNCTION("""COMPUTED_VALUE"""),0.0) -> 0 | U21: =IFERROR(__xludf.DUMMYFUNCTION("""COMPUTED_VALUE"""),1.0) -> 1 | V21: =IFERROR(__xludf.DUMMYFUNCTION("""COMPUTED_VALUE"""),0.0) -> 0 | W21: =IFERROR(__xludf.DUMMYFUNCTION("""COMPUTED_VALUE"""),1.0) -> 1 | X21: =IFERROR(__xludf.DUMMYFUNCTION("""COMPUTED_VALUE"""),"Nhóm 1: Khách tự nhiên vãng lai (Chỉ có HĐ)") -> Nhóm 1: Khách tự nhiên vãng lai (Chỉ có HĐ)
A22: =IFERROR(__xludf.DUMMYFUNCTION("""COMPUTED_VALUE"""),"0934776568") -> 0934776568 | C22: =IFERROR(__xludf.DUMMYFUNCTION("""COMPUTED_VALUE"""),46027.0) -> 46027 | J22: =IFERROR(__xludf.DUMMYFUNCTION("""COMPUTED_VALUE"""),"HD028039") -> HD028039 | K22: =IFERROR(__xludf.DUMMYFUNCTION("""COMPUTED_VALUE"""),"KH009059") -> KH009059 | L22: =IFERROR(__xludf.DUMMYFUNCTION("""COMPUTED_VALUE"""),"(DV) Công nghệ CO2 Fractional - Tách thâm") -> (DV) Công nghệ CO2 Fractional - Tách thâm | M22: =IFERROR(__xludf.DUMMYFUNCTION("""COMPUTED_VALUE"""),1490000.0) -> 1490000 | P22: =IFERROR(__xludf.DUMMYFUNCTION("""COMPUTED_VALUE"""),TRUE) -> TRUE | Q22: =IFERROR(__xludf.DUMMYFUNCTION("""COMPUTED_VALUE"""),"DỊCH VỤ") -> DỊCH VỤ | R22: =IFERROR(__xludf.DUMMYFUNCTION("""COMPUTED_VALUE"""),"Vãng lai") -> Vãng lai | S22: =IFERROR(__xludf.DUMMYFUNCTION("""COMPUTED_VALUE"""),"CO2 / Cắt đáy sẹo") -> CO2 / Cắt đáy sẹo | T22: =IFERROR(__xludf.DUMMYFUNCTION("""COMPUTED_VALUE"""),0.0) -> 0 | U22: =IFERROR(__xludf.DUMMYFUNCTION("""COMPUTED_VALUE"""),1.0) -> 1 | V22: =IFERROR(__xludf.DUMMYFUNCTION("""COMPUTED_VALUE"""),0.0) -> 0 | W22: =IFERROR(__xludf.DUMMYFUNCTION("""COMPUTED_VALUE"""),1.0) -> 1 | X22: =IFERROR(__xludf.DUMMYFUNCTION("""COMPUTED_VALUE"""),"Nhóm 1: Khách tự nhiên vãng lai (Chỉ có HĐ)") -> Nhóm 1: Khách tự nhiên vãng lai (Chỉ có HĐ)
A23: =IFERROR(__xludf.DUMMYFUNCTION("""COMPUTED_VALUE"""),"0906380544") -> 0906380544 | C23: =IFERROR(__xludf.DUMMYFUNCTION("""COMPUTED_VALUE"""),46027.0) -> 46027 | J23: =IFERROR(__xludf.DUMMYFUNCTION("""COMPUTED_VALUE"""),"HD028040") -> HD028040 | K23: =IFERROR(__xludf.DUMMYFUNCTION("""COMPUTED_VALUE"""),"KH009052") -> KH009052 | L23: =IFERROR(__xludf.DUMMYFUNCTION("""COMPUTED_VALUE"""),"(DV) Công nghệ CO2 Fractional - Tách thâm") -> (DV) Công nghệ CO2 Fractional - Tách thâm | M23: =IFERROR(__xludf.DUMMYFUNCTION("""COMPUTED_VALUE"""),990000.0) -> 990000 | P23: =IFERROR(__xludf.DUMMYFUNCTION("""COMPUTED_VALUE"""),TRUE) -> TRUE | Q23: =IFERROR(__xludf.DUMMYFUNCTION("""COMPUTED_VALUE"""),"DỊCH VỤ") -> DỊCH VỤ | R23: =IFERROR(__xludf.DUMMYFUNCTION("""COMPUTED_VALUE"""),"Vãng lai") -> Vãng lai | S23: =IFERROR(__xludf.DUMMYFUNCTION("""COMPUTED_VALUE"""),"CO2 / Cắt đáy sẹo") -> CO2 / Cắt đáy sẹo | T23: =IFERROR(__xludf.DUMMYFUNCTION("""COMPUTED_VALUE"""),0.0) -> 0 | U23: =IFERROR(__xludf.DUMMYFUNCTION("""COMPUTED_VALUE"""),1.0) -> 1 | V23: =IFERROR(__xludf.DUMMYFUNCTION("""COMPUTED_VALUE"""),0.0) -> 0 | W23: =IFERROR(__xludf.DUMMYFUNCTION("""COMPUTED_VALUE"""),1.0) -> 1 | X23: =IFERROR(__xludf.DUMMYFUNCTION("""COMPUTED_VALUE"""),"Nhóm 1: Khách tự nhiên vãng lai (Chỉ có HĐ)") -> Nhóm 1: Khách tự nhiên vãng lai (Chỉ có HĐ)
A24: =IFERROR(__xludf.DUMMYFUNCTION("""COMPUTED_VALUE"""),"0934776568") -> 0934776568 | C24: =IFERROR(__xludf.DUMMYFUNCTION("""COMPUTED_VALUE"""),46027.0) -> 46027 | J24: =IFERROR(__xludf.DUMMYFUNCTION("""COMPUTED_VALUE"""),"HD028041") -> HD028041 | K24: =IFERROR(__xludf.DUMMYFUNCTION("""COMPUTED_VALUE"""),"KH009059") -> KH009059 | L24: =IFERROR(__xludf.DUMMYFUNCTION("""COMPUTED_VALUE"""),"(DV) GÓI TIẾT KIỆM - XÓA CHÂN MÀY TRỌN GÓI") -> (DV) GÓI TIẾT KIỆM - XÓA CHÂN MÀY TRỌN GÓI | M24: =IFERROR(__xludf.DUMMYFUNCTION("""COMPUTED_VALUE"""),0.0) -> 0 | P24: =IFERROR(__xludf.DUMMYFUNCTION("""COMPUTED_VALUE"""),TRUE) -> TRUE | Q24: =IFERROR(__xludf.DUMMYFUNCTION("""COMPUTED_VALUE"""),"DỊCH VỤ") -> DỊCH VỤ | R24: =IFERROR(__xludf.DUMMYFUNCTION("""COMPUTED_VALUE"""),"Vãng lai") -> Vãng lai | S24: =IFERROR(__xludf.DUMMYFUNCTION("""COMPUTED_VALUE"""),"Xóa Laser") -> Xóa Laser | T24: =IFERROR(__xludf.DUMMYFUNCTION("""COMPUTED_VALUE"""),0.0) -> 0 | U24: =IFERROR(__xludf.DUMMYFUNCTION("""COMPUTED_VALUE"""),1.0) -> 1 | V24: =IFERROR(__xludf.DUMMYFUNCTION("""COMPUTED_VALUE"""),0.0) -> 0 | W24: =IFERROR(__xludf.DUMMYFUNCTION("""COMPUTED_VALUE"""),1.0) -> 1 | X24: =IFERROR(__xludf.DUMMYFUNCTION("""COMPUTED_VALUE"""),"Nhóm 1: Khách tự nhiên vãng lai (Chỉ có HĐ)") -> Nhóm 1: Khách tự nhiên vãng lai (Chỉ có HĐ)
A25: =IFERROR(__xludf.DUMMYFUNCTION("""COMPUTED_VALUE"""),"0706156010") -> 0706156010 | C25: =IFERROR(__xludf.DUMMYFUNCTION("""COMPUTED_VALUE"""),46027.0) -> 46027 | J25: =IFERROR(__xludf.DUMMYFUNCTION("""COMPUTED_VALUE"""),"HD028042") -> HD028042 | K25: =IFERROR(__xludf.DUMMYFUNCTION("""COMPUTED_VALUE"""),"KH001950") -> KH001950 | L25: =IFERROR(__xludf.DUMMYFUNCTION("""COMPUTED_VALUE"""),"(DV) Double bóc tách - GOLD") -> (DV) Double bóc tách - GOLD | M25: =IFERROR(__xludf.DUMMYFUNCTION("""COMPUTED_VALUE"""),1760000.0) -> 1760000 | P25: =IFERROR(__xludf.DUMMYFUNCTION("""COMPUTED_VALUE"""),FALSE) -> FALSE | Q25: =IFERROR(__xludf.DUMMYFUNCTION("""COMPUTED_VALUE"""),"DỊCH VỤ") -> DỊCH VỤ | R25: =IFERROR(__xludf.DUMMYFUNCTION("""COMPUTED_VALUE"""),"Vãng lai") -> Vãng lai | S25: =IFERROR(__xludf.DUMMYFUNCTION("""COMPUTED_VALUE"""),"CO2 / Cắt đáy sẹo") -> CO2 / Cắt đáy sẹo | T25: =IFERROR(__xludf.DUMMYFUNCTION("""COMPUTED_VALUE"""),0.0) -> 0 | U25: =IFERROR(__xludf.DUMMYFUNCTION("""COMPUTED_VALUE"""),1.0) -> 1 | V25: =IFERROR(__xludf.DUMMYFUNCTION("""COMPUTED_VALUE"""),0.0) -> 0 | W25: =IFERROR(__xludf.DUMMYFUNCTION("""COMPUTED_VALUE"""),1.0) -> 1 | X25: =IFERROR(__xludf.DUMMYFUNCTION("""COMPUTED_VALUE"""),"Nhóm 1: Khách tự nhiên vãng lai (Chỉ có HĐ)") -> Nhóm 1: Khách tự nhiên vãng lai (Chỉ có HĐ)
A26: =IFERROR(__xludf.DUMMYFUNCTION("""COMPUTED_VALUE"""),"0913829298") -> 0913829298 | C26: =IFERROR(__xludf.DUMMYFUNCTION("""COMPUTED_VALUE"""),46027.0) -> 46027 | J26: =IFERROR(__xludf.DUMMYFUNCTION("""COMPUTED_VALUE"""),"HD028043") -> HD028043 | K26: =IFERROR(__xludf.DUMMYFUNCTION("""COMPUTED_VALUE"""),"KH009060") -> KH009060 | L26: =IFERROR(__xludf.DUMMYFUNCTION("""COMPUTED_VALUE"""),"(DV) Tạo sợi tả thực [NỮ] - GIẢNG VIÊN") -> (DV) Tạo sợi tả thực [NỮ] - GIẢNG VIÊN | M26: =IFERROR(__xludf.DUMMYFUNCTION("""COMPUTED_VALUE"""),7800000.0) -> 7800000 | P26: =IFERROR(__xludf.DUMMYFUNCTION("""COMPUTED_VALUE"""),FALSE) -> FALSE | Q26: =IFERROR(__xludf.DUMMYFUNCTION("""COMPUTED_VALUE"""),"DỊCH VỤ") -> DỊCH VỤ | R26: =IFERROR(__xludf.DUMMYFUNCTION("""COMPUTED_VALUE"""),"Vãng lai") -> Vãng lai | S26: =IFERROR(__xludf.DUMMYFUNCTION("""COMPUTED_VALUE"""),"Làm Mày") -> Làm Mày | T26: =IFERROR(__xludf.DUMMYFUNCTION("""COMPUTED_VALUE"""),0.0) -> 0 | U26: =IFERROR(__xludf.DUMMYFUNCTION("""COMPUTED_VALUE"""),1.0) -> 1 | V26: =IFERROR(__xludf.DUMMYFUNCTION("""COMPUTED_VALUE"""),0.0) -> 0 | W26: =IFERROR(__xludf.DUMMYFUNCTION("""COMPUTED_VALUE"""),1.0) -> 1 | X26: =IFERROR(__xludf.DUMMYFUNCTION("""COMPUTED_VALUE"""),"Nhóm 1: Khách tự nhiên vãng lai (Chỉ có HĐ)") -> Nhóm 1: Khách tự nhiên vãng lai (Chỉ có HĐ)
A27: =IFERROR(__xludf.DUMMYFUNCTION("""COMPUTED_VALUE"""),"0704199298") -> 0704199298 | C27: =IFERROR(__xludf.DUMMYFUNCTION("""COMPUTED_VALUE"""),46027.0) -> 46027 | J27: =IFERROR(__xludf.DUMMYFUNCTION("""COMPUTED_VALUE"""),"HD028044") -> HD028044 | K27: =IFERROR(__xludf.DUMMYFUNCTION("""COMPUTED_VALUE"""),"KH009057") -> KH009057 | L27: =IFERROR(__xludf.DUMMYFUNCTION("""COMPUTED_VALUE"""),"(DV) Công nghệ CO2 Fractional - Tách thâm") -> (DV) Công nghệ CO2 Fractional - Tách thâm | M27: =IFERROR(__xludf.DUMMYFUNCTION("""COMPUTED_VALUE"""),2490000.0) -> 2490000 | P27: =IFERROR(__xludf.DUMMYFUNCTION("""COMPUTED_VALUE"""),TRUE) -> TRUE | Q27: =IFERROR(__xludf.DUMMYFUNCTION("""COMPUTED_VALUE"""),"DỊCH VỤ") -> DỊCH VỤ | R27: =IFERROR(__xludf.DUMMYFUNCTION("""COMPUTED_VALUE"""),"Vãng lai") -> Vãng lai | S27: =IFERROR(__xludf.DUMMYFUNCTION("""COMPUTED_VALUE"""),"CO2 / Cắt đáy sẹo") -> CO2 / Cắt đáy sẹo | T27: =IFERROR(__xludf.DUMMYFUNCTION("""COMPUTED_VALUE"""),0.0) -> 0 | U27: =IFERROR(__xludf.DUMMYFUNCTION("""COMPUTED_VALUE"""),1.0) -> 1 | V27: =IFERROR(__xludf.DUMMYFUNCTION("""COMPUTED_VALUE"""),0.0) -> 0 | W27: =IFERROR(__xludf.DUMMYFUNCTION("""COMPUTED_VALUE"""),1.0) -> 1 | X27: =IFERROR(__xludf.DUMMYFUNCTION("""COMPUTED_VALUE"""),"Nhóm 1: Khách tự nhiên vãng lai (Chỉ có HĐ)") -> Nhóm 1: Khách tự nhiên vãng lai (Chỉ có HĐ)
A28: =IFERROR(__xludf.DUMMYFUNCTION("""COMPUTED_VALUE"""),"0908066006") -> 0908066006 | C28: =IFERROR(__xludf.DUMMYFUNCTION("""COMPUTED_VALUE"""),46028.0) -> 46028 | J28: =IFERROR(__xludf.DUMMYFUNCTION("""COMPUTED_VALUE"""),"HD028045") -> HD028045 | K28: =IFERROR(__xludf.DUMMYFUNCTION("""COMPUTED_VALUE"""),"KH008398") -> KH008398 | L28: =IFERROR(__xludf.DUMMYFUNCTION("""COMPUTED_VALUE"""),"(DV) Tạo sợi tả thực [NỮ] - GIẢNG VIÊN") -> (DV) Tạo sợi tả thực [NỮ] - GIẢNG VIÊN | M28: =IFERROR(__xludf.DUMMYFUNCTION("""COMPUTED_VALUE"""),7800000.0) -> 7800000 | P28: =IFERROR(__xludf.DUMMYFUNCTION("""COMPUTED_VALUE"""),FALSE) -> FALSE | Q28: =IFERROR(__xludf.DUMMYFUNCTION("""COMPUTED_VALUE"""),"DỊCH VỤ") -> DỊCH VỤ | R28: =IFERROR(__xludf.DUMMYFUNCTION("""COMPUTED_VALUE"""),"Vãng lai") -> Vãng lai | S28: =IFERROR(__xludf.DUMMYFUNCTION("""COMPUTED_VALUE"""),"Làm Mày") -> Làm Mày | T28: =IFERROR(__xludf.DUMMYFUNCTION("""COMPUTED_VALUE"""),0.0) -> 0 | U28: =IFERROR(__xludf.DUMMYFUNCTION("""COMPUTED_VALUE"""),1.0) -> 1 | V28: =IFERROR(__xludf.DUMMYFUNCTION("""COMPUTED_VALUE"""),0.0) -> 0 | W28: =IFERROR(__xludf.DUMMYFUNCTION("""COMPUTED_VALUE"""),1.0) -> 1 | X28: =IFERROR(__xludf.DUMMYFUNCTION("""COMPUTED_VALUE"""),"Nhóm 1: Khách tự nhiên vãng lai (Chỉ có HĐ)") -> Nhóm 1: Khách tự nhiên vãng lai (Chỉ có HĐ)
A29: =IFERROR(__xludf.DUMMYFUNCTION("""COMPUTED_VALUE"""),"0949100294") -> 0949100294 | C29: =IFERROR(__xludf.DUMMYFUNCTION("""COMPUTED_VALUE"""),46028.0) -> 46028 | J29: =IFERROR(__xludf.DUMMYFUNCTION("""COMPUTED_VALUE"""),"HD028046") -> HD028046 | K29: =IFERROR(__xludf.DUMMYFUNCTION("""COMPUTED_VALUE"""),"KH008546") -> KH008546 | L29: =IFERROR(__xludf.DUMMYFUNCTION("""COMPUTED_VALUE"""),"(DV) Tạo sợi tả thực [NỮ] - DIAMOND") -> (DV) Tạo sợi tả thực [NỮ] - DIAMOND | M29: =IFERROR(__xludf.DUMMYFUNCTION("""COMPUTED_VALUE"""),9720000.0) -> 9720000 | P29: =IFERROR(__xludf.DUMMYFUNCTION("""COMPUTED_VALUE"""),FALSE) -> FALSE | Q29: =IFERROR(__xludf.DUMMYFUNCTION("""COMPUTED_VALUE"""),"DỊCH VỤ") -> DỊCH VỤ | R29: =IFERROR(__xludf.DUMMYFUNCTION("""COMPUTED_VALUE"""),"Vãng lai") -> Vãng lai | S29: =IFERROR(__xludf.DUMMYFUNCTION("""COMPUTED_VALUE"""),"Làm Mày") -> Làm Mày | T29: =IFERROR(__xludf.DUMMYFUNCTION("""COMPUTED_VALUE"""),0.0) -> 0 | U29: =IFERROR(__xludf.DUMMYFUNCTION("""COMPUTED_VALUE"""),1.0) -> 1 | V29: =IFERROR(__xludf.DUMMYFUNCTION("""COMPUTED_VALUE"""),0.0) -> 0 | W29: =IFERROR(__xludf.DUMMYFUNCTION("""COMPUTED_VALUE"""),1.0) -> 1 | X29: =IFERROR(__xludf.DUMMYFUNCTION("""COMPUTED_VALUE"""),"Nhóm 1: Khách tự nhiên vãng lai (Chỉ có HĐ)") -> Nhóm 1: Khách tự nhiên vãng lai (Chỉ có HĐ)
A30: =IFERROR(__xludf.DUMMYFUNCTION("""COMPUTED_VALUE"""),"0949100294") -> 0949100294 | C30: =IFERROR(__xludf.DUMMYFUNCTION("""COMPUTED_VALUE"""),46028.0) -> 46028 | J30: =IFERROR(__xludf.DUMMYFUNCTION("""COMPUTED_VALUE"""),"HD028047") -> HD028047 | K30: =IFERROR(__xludf.DUMMYFUNCTION("""COMPUTED_VALUE"""),"KH008546") -> KH008546 | L30: =IFERROR(__xludf.DUMMYFUNCTION("""COMPUTED_VALUE"""),"(DV) Trẻ hóa da (vùng mặt) (trọn gói)") -> (DV) Trẻ hóa da (vùng mặt) (trọn gói) | M30: =IFERROR(__xludf.DUMMYFUNCTION("""COMPUTED_VALUE"""),2490000.0) -> 2490000 | P30: =IFERROR(__xludf.DUMMYFUNCTION("""COMPUTED_VALUE"""),FALSE) -> FALSE | Q30: =IFERROR(__xludf.DUMMYFUNCTION("""COMPUTED_VALUE"""),"DỊCH VỤ") -> DỊCH VỤ | R30: =IFERROR(__xludf.DUMMYFUNCTION("""COMPUTED_VALUE"""),"Vãng lai") -> Vãng lai | S30: =IFERROR(__xludf.DUMMYFUNCTION("""COMPUTED_VALUE"""),"Dịch vụ/Sản phẩm khác") -> Dịch vụ/Sản phẩm khác | T30: =IFERROR(__xludf.DUMMYFUNCTION("""COMPUTED_VALUE"""),0.0) -> 0 | U30: =IFERROR(__xludf.DUMMYFUNCTION("""COMPUTED_VALUE"""),1.0) -> 1 | V30: =IFERROR(__xludf.DUMMYFUNCTION("""COMPUTED_VALUE"""),0.0) -> 0 | W30: =IFERROR(__xludf.DUMMYFUNCTION("""COMPUTED_VALUE"""),1.0) -> 1 | X30: =IFERROR(__xludf.DUMMYFUNCTION("""COMPUTED_VALUE"""),"Nhóm 1: Khách tự nhiên vãng lai (Chỉ có HĐ)") -> Nhóm 1: Khách tự nhiên vãng lai (Chỉ có HĐ)
A31: =IFERROR(__xludf.DUMMYFUNCTION("""COMPUTED_VALUE"""),"0937637772") -> 0937637772 | C31: =IFERROR(__xludf.DUMMYFUNCTION("""COMPUTED_VALUE"""),46028.0) -> 46028 | J31: =IFERROR(__xludf.DUMMYFUNCTION("""COMPUTED_VALUE"""),"HD028048") -> HD028048 | K31: =IFERROR(__xludf.DUMMYFUNCTION("""COMPUTED_VALUE"""),"KH008547") -> KH008547 | L31: =IFERROR(__xludf.DUMMYFUNCTION("""COMPUTED_VALUE"""),"(DV) Trẻ hóa da (vùng mặt) (trọn gói)") -> (DV) Trẻ hóa da (vùng mặt) (trọn gói) | M31: =IFERROR(__xludf.DUMMYFUNCTION("""COMPUTED_VALUE"""),1990000.0) -> 1990000 | P31: =IFERROR(__xludf.DUMMYFUNCTION("""COMPUTED_VALUE"""),FALSE) -> FALSE | Q31: =IFERROR(__xludf.DUMMYFUNCTION("""COMPUTED_VALUE"""),"DỊCH VỤ") -> DỊCH VỤ | R31: =IFERROR(__xludf.DUMMYFUNCTION("""COMPUTED_VALUE"""),"Vãng lai") -> Vãng lai | S31: =IFERROR(__xludf.DUMMYFUNCTION("""COMPUTED_VALUE"""),"Dịch vụ/Sản phẩm khác") -> Dịch vụ/Sản phẩm khác | T31: =IFERROR(__xludf.DUMMYFUNCTION("""COMPUTED_VALUE"""),0.0) -> 0 | U31: =IFERROR(__xludf.DUMMYFUNCTION("""COMPUTED_VALUE"""),1.0) -> 1 | V31: =IFERROR(__xludf.DUMMYFUNCTION("""COMPUTED_VALUE"""),0.0) -> 0 | W31: =IFERROR(__xludf.DUMMYFUNCTION("""COMPUTED_VALUE"""),1.0) -> 1 | X31: =IFERROR(__xludf.DUMMYFUNCTION("""COMPUTED_VALUE"""),"Nhóm 1: Khách tự nhiên vãng lai (Chỉ có HĐ)") -> Nhóm 1: Khách tự nhiên vãng lai (Chỉ có HĐ)
A32: =IFERROR(__xludf.DUMMYFUNCTION("""COMPUTED_VALUE"""),"0937637772") -> 0937637772 | C32: =IFERROR(__xludf.DUMMYFUNCTION("""COMPUTED_VALUE"""),46028.0) -> 46028 | J32: =IFERROR(__xludf.DUMMYFUNCTION("""COMPUTED_VALUE"""),"HD028049") -> HD028049 | K32: =IFERROR(__xludf.DUMMYFUNCTION("""COMPUTED_VALUE"""),"KH008547") -> KH008547 | L32: =IFERROR(__xludf.DUMMYFUNCTION("""COMPUTED_VALUE"""),"(DV) Tạo sợi tả thực [NỮ] - CÔ HƯỜNG") -> (DV) Tạo sợi tả thực [NỮ] - CÔ HƯỜNG | M32: =IFERROR(__xludf.DUMMYFUNCTION("""COMPUTED_VALUE"""),2.03E7) -> 20300000 | P32: =IFERROR(__xludf.DUMMYFUNCTION("""COMPUTED_VALUE"""),FALSE) -> FALSE | Q32: =IFERROR(__xludf.DUMMYFUNCTION("""COMPUTED_VALUE"""),"DỊCH VỤ") -> DỊCH VỤ | R32: =IFERROR(__xludf.DUMMYFUNCTION("""COMPUTED_VALUE"""),"Vãng lai") -> Vãng lai | S32: =IFERROR(__xludf.DUMMYFUNCTION("""COMPUTED_VALUE"""),"Làm Mày") -> Làm Mày | T32: =IFERROR(__xludf.DUMMYFUNCTION("""COMPUTED_VALUE"""),0.0) -> 0 | U32: =IFERROR(__xludf.DUMMYFUNCTION("""COMPUTED_VALUE"""),1.0) -> 1 | V32: =IFERROR(__xludf.DUMMYFUNCTION("""COMPUTED_VALUE"""),0.0) -> 0 | W32: =IFERROR(__xludf.DUMMYFUNCTION("""COMPUTED_VALUE"""),1.0) -> 1 | X32: =IFERROR(__xludf.DUMMYFUNCTION("""COMPUTED_VALUE"""),"Nhóm 1: Khách tự nhiên vãng lai (Chỉ có HĐ)") -> Nhóm 1: Khách tự nhiên vãng lai (Chỉ có HĐ)
A33: =IFERROR(__xludf.DUMMYFUNCTION("""COMPUTED_VALUE"""),"0775345543") -> 0775345543 | C33: =IFERROR(__xludf.DUMMYFUNCTION("""COMPUTED_VALUE"""),46028.0) -> 46028 | J33: =IFERROR(__xludf.DUMMYFUNCTION("""COMPUTED_VALUE"""),"HD028050") -> HD028050 | K33: =IFERROR(__xludf.DUMMYFUNCTION("""COMPUTED_VALUE"""),"KH009061") -> KH009061 | L33: =IFERROR(__xludf.DUMMYFUNCTION("""COMPUTED_VALUE"""),"(DV) Tạo sợi tả thực (NỮ) - GOLD") -> (DV) Tạo sợi tả thực (NỮ) - GOLD | M33: =IFERROR(__xludf.DUMMYFUNCTION("""COMPUTED_VALUE"""),3390000.0) -> 3390000 | P33: =IFERROR(__xludf.DUMMYFUNCTION("""COMPUTED_VALUE"""),FALSE) -> FALSE | Q33: =IFERROR(__xludf.DUMMYFUNCTION("""COMPUTED_VALUE"""),"DỊCH VỤ") -> DỊCH VỤ | R33: =IFERROR(__xludf.DUMMYFUNCTION("""COMPUTED_VALUE"""),"Vãng lai") -> Vãng lai | S33: =IFERROR(__xludf.DUMMYFUNCTION("""COMPUTED_VALUE"""),"Làm Mày") -> Làm Mày | T33: =IFERROR(__xludf.DUMMYFUNCTION("""COMPUTED_VALUE"""),0.0) -> 0 | U33: =IFERROR(__xludf.DUMMYFUNCTION("""COMPUTED_VALUE"""),1.0) -> 1 | V33: =IFERROR(__xludf.DUMMYFUNCTION("""COMPUTED_VALUE"""),0.0) -> 0 | W33: =IFERROR(__xludf.DUMMYFUNCTION("""COMPUTED_VALUE"""),1.0) -> 1 | X33: =IFERROR(__xludf.DUMMYFUNCTION("""COMPUTED_VALUE"""),"Nhóm 1: Khách tự nhiên vãng lai (Chỉ có HĐ)") -> Nhóm 1: Khách tự nhiên vãng lai (Chỉ có HĐ)
A34: =IFERROR(__xludf.DUMMYFUNCTION("""COMPUTED_VALUE"""),"0357057133") -> 0357057133 | C34: =IFERROR(__xludf.DUMMYFUNCTION("""COMPUTED_VALUE"""),46028.0) -> 46028 | J34: =IFERROR(__xludf.DUMMYFUNCTION("""COMPUTED_VALUE"""),"HD028052") -> HD028052 | K34: =IFERROR(__xludf.DUMMYFUNCTION("""COMPUTED_VALUE"""),"KH008397") -> KH008397 | L34: =IFERROR(__xludf.DUMMYFUNCTION("""COMPUTED_VALUE"""),"(DV) GÓI TIẾT KIỆM - XÓA CHÂN MÀY TRỌN GÓI") -> (DV) GÓI TIẾT KIỆM - XÓA CHÂN MÀY TRỌN GÓI | M34: =IFERROR(__xludf.DUMMYFUNCTION("""COMPUTED_VALUE"""),0.0) -> 0 | P34: =IFERROR(__xludf.DUMMYFUNCTION("""COMPUTED_VALUE"""),TRUE) -> TRUE | Q34: =IFERROR(__xludf.DUMMYFUNCTION("""COMPUTED_VALUE"""),"DỊCH VỤ") -> DỊCH VỤ | R34: =IFERROR(__xludf.DUMMYFUNCTION("""COMPUTED_VALUE"""),"Vãng lai") -> Vãng lai | S34: =IFERROR(__xludf.DUMMYFUNCTION("""COMPUTED_VALUE"""),"Xóa Laser") -> Xóa Laser | T34: =IFERROR(__xludf.DUMMYFUNCTION("""COMPUTED_VALUE"""),0.0) -> 0 | U34: =IFERROR(__xludf.DUMMYFUNCTION("""COMPUTED_VALUE"""),1.0) -> 1 | V34: =IFERROR(__xludf.DUMMYFUNCTION("""COMPUTED_VALUE"""),0.0) -> 0 | W34: =IFERROR(__xludf.DUMMYFUNCTION("""COMPUTED_VALUE"""),1.0) -> 1 | X34: =IFERROR(__xludf.DUMMYFUNCTION("""COMPUTED_VALUE"""),"Nhóm 1: Khách tự nhiên vãng lai (Chỉ có HĐ)") -> Nhóm 1: Khách tự nhiên vãng lai (Chỉ có HĐ)
A35: =IFERROR(__xludf.DUMMYFUNCTION("""COMPUTED_VALUE"""),"0969510292") -> 0969510292 | C35: =IFERROR(__xludf.DUMMYFUNCTION("""COMPUTED_VALUE"""),46028.0) -> 46028 | J35: =IFERROR(__xludf.DUMMYFUNCTION("""COMPUTED_VALUE"""),"HD028053") -> HD028053 | K35: =IFERROR(__xludf.DUMMYFUNCTION("""COMPUTED_VALUE"""),"KH003490") -> KH003490 | L35: =IFERROR(__xludf.DUMMYFUNCTION("""COMPUTED_VALUE"""),"(DV) Tạo sợi tả thực [NỮ] - DIAMOND") -> (DV) Tạo sợi tả thực [NỮ] - DIAMOND | M35: =IFERROR(__xludf.DUMMYFUNCTION("""COMPUTED_VALUE"""),8640000.0) -> 8640000 | P35: =IFERROR(__xludf.DUMMYFUNCTION("""COMPUTED_VALUE"""),FALSE) -> FALSE | Q35: =IFERROR(__xludf.DUMMYFUNCTION("""COMPUTED_VALUE"""),"DỊCH VỤ") -> DỊCH VỤ | R35: =IFERROR(__xludf.DUMMYFUNCTION("""COMPUTED_VALUE"""),"Vãng lai") -> Vãng lai | S35: =IFERROR(__xludf.DUMMYFUNCTION("""COMPUTED_VALUE"""),"Làm Mày") -> Làm Mày | T35: =IFERROR(__xludf.DUMMYFUNCTION("""COMPUTED_VALUE"""),0.0) -> 0 | U35: =IFERROR(__xludf.DUMMYFUNCTION("""COMPUTED_VALUE"""),1.0) -> 1 | V35: =IFERROR(__xludf.DUMMYFUNCTION("""COMPUTED_VALUE"""),0.0) -> 0 | W35: =IFERROR(__xludf.DUMMYFUNCTION("""COMPUTED_VALUE"""),1.0) -> 1 | X35: =IFERROR(__xludf.DUMMYFUNCTION("""COMPUTED_VALUE"""),"Nhóm 1: Khách tự nhiên vãng lai (Chỉ có HĐ)") -> Nhóm 1: Khách tự nhiên vãng lai (Chỉ có HĐ)
A36: =IFERROR(__xludf.DUMMYFUNCTION("""COMPUTED_VALUE"""),"0857326751") -> 0857326751 | C36: =IFERROR(__xludf.DUMMYFUNCTION("""COMPUTED_VALUE"""),46028.0) -> 46028 | J36: =IFERROR(__xludf.DUMMYFUNCTION("""COMPUTED_VALUE"""),"HD028055") -> HD028055 | K36: =IFERROR(__xludf.DUMMYFUNCTION("""COMPUTED_VALUE"""),"KH007718") -> KH007718 | L36: =IFERROR(__xludf.DUMMYFUNCTION("""COMPUTED_VALUE"""),"(DV) GÓI TIẾT KIỆM - XÓA CHÂN MÀY TRỌN GÓI") -> (DV) GÓI TIẾT KIỆM - XÓA CHÂN MÀY TRỌN GÓI | M36: =IFERROR(__xludf.DUMMYFUNCTION("""COMPUTED_VALUE"""),0.0) -> 0 | P36: =IFERROR(__xludf.DUMMYFUNCTION("""COMPUTED_VALUE"""),TRUE) -> TRUE | Q36: =IFERROR(__xludf.DUMMYFUNCTION("""COMPUTED_VALUE"""),"DỊCH VỤ") -> DỊCH VỤ | R36: =IFERROR(__xludf.DUMMYFUNCTION("""COMPUTED_VALUE"""),"Vãng lai") -> Vãng lai | S36: =IFERROR(__xludf.DUMMYFUNCTION("""COMPUTED_VALUE"""),"Xóa Laser") -> Xóa Laser | T36: =IFERROR(__xludf.DUMMYFUNCTION("""COMPUTED_VALUE"""),0.0) -> 0 | U36: =IFERROR(__xludf.DUMMYFUNCTION("""COMPUTED_VALUE"""),1.0) -> 1 | V36: =IFERROR(__xludf.DUMMYFUNCTION("""COMPUTED_VALUE"""),0.0) -> 0 | W36: =IFERROR(__xludf.DUMMYFUNCTION("""COMPUTED_VALUE"""),1.0) -> 1 | X36: =IFERROR(__xludf.DUMMYFUNCTION("""COMPUTED_VALUE"""),"Nhóm 1: Khách tự nhiên vãng lai (Chỉ có HĐ)") -> Nhóm 1: Khách tự nhiên vãng lai (Chỉ có HĐ)
A37: =IFERROR(__xludf.DUMMYFUNCTION("""COMPUTED_VALUE"""),"0906380544") -> 0906380544 | C37: =IFERROR(__xludf.DUMMYFUNCTION("""COMPUTED_VALUE"""),46028.0) -> 46028 | J37: =IFERROR(__xludf.DUMMYFUNCTION("""COMPUTED_VALUE"""),"HD028056") -> HD028056 | K37: =IFERROR(__xludf.DUMMYFUNCTION("""COMPUTED_VALUE"""),"KH009052") -> KH009052 | L37: =IFERROR(__xludf.DUMMYFUNCTION("""COMPUTED_VALUE"""),"(DV) GÓI TIẾT KIỆM - XÓA CHÂN MÀY TRỌN GÓI") -> (DV) GÓI TIẾT KIỆM - XÓA CHÂN MÀY TRỌN GÓI | M37: =IFERROR(__xludf.DUMMYFUNCTION("""COMPUTED_VALUE"""),0.0) -> 0 | P37: =IFERROR(__xludf.DUMMYFUNCTION("""COMPUTED_VALUE"""),TRUE) -> TRUE | Q37: =IFERROR(__xludf.DUMMYFUNCTION("""COMPUTED_VALUE"""),"DỊCH VỤ") -> DỊCH VỤ | R37: =IFERROR(__xludf.DUMMYFUNCTION("""COMPUTED_VALUE"""),"Vãng lai") -> Vãng lai | S37: =IFERROR(__xludf.DUMMYFUNCTION("""COMPUTED_VALUE"""),"Xóa Laser") -> Xóa Laser | T37: =IFERROR(__xludf.DUMMYFUNCTION("""COMPUTED_VALUE"""),0.0) -> 0 | U37: =IFERROR(__xludf.DUMMYFUNCTION("""COMPUTED_VALUE"""),1.0) -> 1 | V37: =IFERROR(__xludf.DUMMYFUNCTION("""COMPUTED_VALUE"""),0.0) -> 0 | W37: =IFERROR(__xludf.DUMMYFUNCTION("""COMPUTED_VALUE"""),1.0) -> 1 | X37: =IFERROR(__xludf.DUMMYFUNCTION("""COMPUTED_VALUE"""),"Nhóm 1: Khách tự nhiên vãng lai (Chỉ có HĐ)") -> Nhóm 1: Khách tự nhiên vãng lai (Chỉ có HĐ)
A38: =IFERROR(__xludf.DUMMYFUNCTION("""COMPUTED_VALUE"""),"0398559073") -> 0398559073 | C38: =IFERROR(__xludf.DUMMYFUNCTION("""COMPUTED_VALUE"""),46028.0) -> 46028 | J38: =IFERROR(__xludf.DUMMYFUNCTION("""COMPUTED_VALUE"""),"HD028060") -> HD028060 | K38: =IFERROR(__xludf.DUMMYFUNCTION("""COMPUTED_VALUE"""),"KH009063") -> KH009063 | L38: =IFERROR(__xludf.DUMMYFUNCTION("""COMPUTED_VALUE"""),"(DV) GÓI TIẾT KIỆM - XÓA CHÂN MÀY TRỌN GÓI") -> (DV) GÓI TIẾT KIỆM - XÓA CHÂN MÀY TRỌN GÓI | M38: =IFERROR(__xludf.DUMMYFUNCTION("""COMPUTED_VALUE"""),0.0) -> 0 | P38: =IFERROR(__xludf.DUMMYFUNCTION("""COMPUTED_VALUE"""),TRUE) -> TRUE | Q38: =IFERROR(__xludf.DUMMYFUNCTION("""COMPUTED_VALUE"""),"DỊCH VỤ") -> DỊCH VỤ | R38: =IFERROR(__xludf.DUMMYFUNCTION("""COMPUTED_VALUE"""),"Vãng lai") -> Vãng lai | S38: =IFERROR(__xludf.DUMMYFUNCTION("""COMPUTED_VALUE"""),"Xóa Laser") -> Xóa Laser | T38: =IFERROR(__xludf.DUMMYFUNCTION("""COMPUTED_VALUE"""),0.0) -> 0 | U38: =IFERROR(__xludf.DUMMYFUNCTION("""COMPUTED_VALUE"""),1.0) -> 1 | V38: =IFERROR(__xludf.DUMMYFUNCTION("""COMPUTED_VALUE"""),0.0) -> 0 | W38: =IFERROR(__xludf.DUMMYFUNCTION("""COMPUTED_VALUE"""),1.0) -> 1 | X38: =IFERROR(__xludf.DUMMYFUNCTION("""COMPUTED_VALUE"""),"Nhóm 1: Khách tự nhiên vãng lai (Chỉ có HĐ)") -> Nhóm 1: Khách tự nhiên vãng lai (Chỉ có HĐ)
A39: =IFERROR(__xludf.DUMMYFUNCTION("""COMPUTED_VALUE"""),"0909008714") -> 0909008714 | C39: =IFERROR(__xludf.DUMMYFUNCTION("""COMPUTED_VALUE"""),46028.0) -> 46028 | J39: =IFERROR(__xludf.DUMMYFUNCTION("""COMPUTED_VALUE"""),"HD028061") -> HD028061 | K39: =IFERROR(__xludf.DUMMYFUNCTION("""COMPUTED_VALUE"""),"KH009064") -> KH009064 | L39: =IFERROR(__xludf.DUMMYFUNCTION("""COMPUTED_VALUE"""),"(DV) GÓI TIẾT KIỆM - XÓA CHÂN MÀY TRỌN GÓI") -> (DV) GÓI TIẾT KIỆM - XÓA CHÂN MÀY TRỌN GÓI | M39: =IFERROR(__xludf.DUMMYFUNCTION("""COMPUTED_VALUE"""),0.0) -> 0 | P39: =IFERROR(__xludf.DUMMYFUNCTION("""COMPUTED_VALUE"""),TRUE) -> TRUE | Q39: =IFERROR(__xludf.DUMMYFUNCTION("""COMPUTED_VALUE"""),"DỊCH VỤ") -> DỊCH VỤ | R39: =IFERROR(__xludf.DUMMYFUNCTION("""COMPUTED_VALUE"""),"Vãng lai") -> Vãng lai | S39: =IFERROR(__xludf.DUMMYFUNCTION("""COMPUTED_VALUE"""),"Xóa Laser") -> Xóa Laser | T39: =IFERROR(__xludf.DUMMYFUNCTION("""COMPUTED_VALUE"""),0.0) -> 0 | U39: =IFERROR(__xludf.DUMMYFUNCTION("""COMPUTED_VALUE"""),1.0) -> 1 | V39: =IFERROR(__xludf.DUMMYFUNCTION("""COMPUTED_VALUE"""),0.0) -> 0 | W39: =IFERROR(__xludf.DUMMYFUNCTION("""COMPUTED_VALUE"""),1.0) -> 1 | X39: =IFERROR(__xludf.DUMMYFUNCTION("""COMPUTED_VALUE"""),"Nhóm 1: Khách tự nhiên vãng lai (Chỉ có HĐ)") -> Nhóm 1: Khách tự nhiên vãng lai (Chỉ có HĐ)
A40: =IFERROR(__xludf.DUMMYFUNCTION("""COMPUTED_VALUE"""),"0856142147") -> 0856142147 | C40: =IFERROR(__xludf.DUMMYFUNCTION("""COMPUTED_VALUE"""),46028.0) -> 46028 | J40: =IFERROR(__xludf.DUMMYFUNCTION("""COMPUTED_VALUE"""),"HD028063") -> HD028063 | K40: =IFERROR(__xludf.DUMMYFUNCTION("""COMPUTED_VALUE"""),"KH009065") -> KH009065 | L40: =IFERROR(__xludf.DUMMYFUNCTION("""COMPUTED_VALUE"""),"(DV) GÓI TIẾT KIỆM - XÓA CHÂN MÀY TRỌN GÓI") -> (DV) GÓI TIẾT KIỆM - XÓA CHÂN MÀY TRỌN GÓI | M40: =IFERROR(__xludf.DUMMYFUNCTION("""COMPUTED_VALUE"""),0.0) -> 0 | P40: =IFERROR(__xludf.DUMMYFUNCTION("""COMPUTED_VALUE"""),TRUE) -> TRUE | Q40: =IFERROR(__xludf.DUMMYFUNCTION("""COMPUTED_VALUE"""),"DỊCH VỤ") -> DỊCH VỤ | R40: =IFERROR(__xludf.DUMMYFUNCTION("""COMPUTED_VALUE"""),"Vãng lai") -> Vãng lai | S40: =IFERROR(__xludf.DUMMYFUNCTION("""COMPUTED_VALUE"""),"Xóa Laser") -> Xóa Laser | T40: =IFERROR(__xludf.DUMMYFUNCTION("""COMPUTED_VALUE"""),0.0) -> 0 | U40: =IFERROR(__xludf.DUMMYFUNCTION("""COMPUTED_VALUE"""),1.0) -> 1 | V40: =IFERROR(__xludf.DUMMYFUNCTION("""COMPUTED_VALUE"""),0.0) -> 0 | W40: =IFERROR(__xludf.DUMMYFUNCTION("""COMPUTED_VALUE"""),1.0) -> 1 | X40: =IFERROR(__xludf.DUMMYFUNCTION("""COMPUTED_VALUE"""),"Nhóm 1: Khách tự nhiên vãng lai (Chỉ có HĐ)") -> Nhóm 1: Khách tự nhiên vãng lai (Chỉ có HĐ)
...

Sheet KiotViet
A1: Mã hóa đơn | B1: Thời gian | C1: Mã khách hàng | D1: Tên khách hàng | E1: Điện thoại | F1: Người bán | G1: Khách cần trả | H1: Mã hàng | I1: Tên hàng | J1: Số lượng | K1: (paste-zone) | L1: (paste-zone) | M1: (paste-zone) | N1: SĐT Cuối (AUTO)
A2: HD028001 | B2: 46026.452 | C2: KH004211 | D2: Chị Cầm | E2: 0389557477 | F2: Yến Nhi | G2: 9420000 | H2: SP028168 | I2: (DV) Tạo sợi tả thực [NỮ] - DIAMOND | J2: 1 | N2: =IFERROR(__xludf.DUMMYFUNCTION("IF(E2="""","""",""0"" & REGEXREPLACE(REGEXREPLACE(E2&"""",""[^0-9]"",""""),""^0+"",""""))"),"0389557477") -> 0389557477
A3: HD028004 | B3: 46026.577 | C3: KH009044 | D3: Thu Nguyệt | E3: 0988887727 | F3: Nguyễn Sang | G3: 900000 | H3: SP000558 | I3: (DV) GÓI TIẾT KIỆM - XÓA CHÂN MÀY TRỌN GÓI | J3: 1 | N3: =IFERROR(__xludf.DUMMYFUNCTION("IF(E3="""","""",""0"" & REGEXREPLACE(REGEXREPLACE(E3&"""",""[^0-9]"",""""),""^0+"",""""))"),"0988887727") -> 0988887727
A4: HD028006.01 | B4: 46026.601 | C4: KH009045 | D4: Xuân Yến (BV Phương Châu) | E4: 0985868707 | F4: Hường Cao Vic | G4: 15030000 | H4: SP000003 | I4: (DV) Phun Môi - CÔ HƯỜNG | J4: 1 | N4: =IFERROR(__xludf.DUMMYFUNCTION("IF(E4="""","""",""0"" & REGEXREPLACE(REGEXREPLACE(E4&"""",""[^0-9]"",""""),""^0+"",""""))"),"0985868707") -> 0985868707
A5: HD028011 | B5: 46026.701 | C5: KH009044 | D5: Thu Nguyệt | E5: 0988887727 | F5: Thanh Hải | G5: 3490000 | H5: SP000010 | I5: (DV) Khử thâm + Phun môi - GOLD | J5: 1 | N5: =IFERROR(__xludf.DUMMYFUNCTION("IF(E5="""","""",""0"" & REGEXREPLACE(REGEXREPLACE(E5&"""",""[^0-9]"",""""),""^0+"",""""))"),"0988887727") -> 0988887727
A6: HD028012 | B6: 46026.703 | C6: KH008410 | D6: Nguyễn Diệu Ngọc Tuyền | E6: 0908436728 | F6: Hường Cao Vic | G6: 17970000 | H6: SP000223 | I6: (DV) Tạo sợi tả thực [NỮ] - CÔ HƯỜNG | J6: 1 | N6: =IFERROR(__xludf.DUMMYFUNCTION("IF(E6="""","""",""0"" & REGEXREPLACE(REGEXREPLACE(E6&"""",""[^0-9]"",""""),""^0+"",""""))"),"0908436728") -> 0908436728
A7: HD028013 | B7: 46026.704 | C7: KH009046 | D7: Huyền | E7: 0565867163 | F7: Nguyễn Sang | G7: 900000 | H7: SP000558 | I7: (DV) GÓI TIẾT KIỆM - XÓA CHÂN MÀY TRỌN GÓI | J7: 1 | N7: =IFERROR(__xludf.DUMMYFUNCTION("IF(E7="""","""",""0"" & REGEXREPLACE(REGEXREPLACE(E7&"""",""[^0-9]"",""""),""^0+"",""""))"),"0565867163") -> 0565867163
A8: HD028014 | B8: 46026.706 | C8: KH008349 | D8: Chị Huệ | E8: 0974992869 | F8: Thanh Trân | G8: 2700000 | H8: SP000011 | I8: (DV) Double bóc tách - GOLD | J8: 1 | N8: =IFERROR(__xludf.DUMMYFUNCTION("IF(E8="""","""",""0"" & REGEXREPLACE(REGEXREPLACE(E8&"""",""[^0-9]"",""""),""^0+"",""""))"),"0974992869") -> 0974992869
A9: HD028016 | B9: 46026.709 | C9: KH009043 | D9: Evan - Ngọc | E9: 0896146217 | F9: Thanh Phương | G9: 10800000 | H9: SP028168 | I9: (DV) Tạo sợi tả thực [NỮ] - DIAMOND | J9: 1 | N9: =IFERROR(__xludf.DUMMYFUNCTION("IF(E9="""","""",""0"" & REGEXREPLACE(REGEXREPLACE(E9&"""",""[^0-9]"",""""),""^0+"",""""))"),"0896146217") -> 0896146217
A10: HD028017 | B10: 46026.71 | C10: KH009043 | D10: Evan - Ngọc | E10: 0896146217 | F10: Yến Nhi | G10: 8100000 | H10: SP028166 | I10: (DV) Double bóc tách - DIAMOND | J10: 1 | N10: =IFERROR(__xludf.DUMMYFUNCTION("IF(E10="""","""",""0"" & REGEXREPLACE(REGEXREPLACE(E10&"""",""[^0-9]"",""""),""^0+"",""""))"),"0896146217") -> 0896146217
A11: HD028018 | B11: 46026.715 | C11: KH009047 | D11: Phương Thảo | E11: 0909616797 | F11: Nguyễn Sang | G11: 900000 | H11: SP000558 | I11: (DV) GÓI TIẾT KIỆM - XÓA CHÂN MÀY TRỌN GÓI | J11: 1 | N11: =IFERROR(__xludf.DUMMYFUNCTION("IF(E11="""","""",""0"" & REGEXREPLACE(REGEXREPLACE(E11&"""",""[^0-9]"",""""),""^0+"",""""))"),"0909616797") -> 0909616797
A12: HD028019 | B12: 46026.722 | C12: KH009047 | D12: Phương Thảo | E12: 0909616797 | F12: Nguyễn Sang | G12: 1490000 | H12: SP002859 | I12: (DV) Công nghệ CO2 Fractional - Tách thâm | J12: 1 | N12: =IFERROR(__xludf.DUMMYFUNCTION("IF(E12="""","""",""0"" & REGEXREPLACE(REGEXREPLACE(E12&"""",""[^0-9]"",""""),""^0+"",""""))"),"0909616797") -> 0909616797
A13: HD028020 | B13: 46026.724 | C13: KH009048 | D13: Phương | E13: 0939431555 | F13: Thanh Phương | G13: 6600000 | H13: SP028202 | I13: (DV) Xử lý nền + Phun môi - PLATINUM | J13: 1 | N13: =IFERROR(__xludf.DUMMYFUNCTION("IF(E13="""","""",""0"" & REGEXREPLACE(REGEXREPLACE(E13&"""",""[^0-9]"",""""),""^0+"",""""))"),"0939431555") -> 0939431555
A14: HD028021 | B14: 46026.725 | C14: KH009049 | D14: Phan Ngọc Trâm | E14: 0989413672 | F14: Nguyễn Sang | G14: 900000 | H14: SP000558 | I14: (DV) GÓI TIẾT KIỆM - XÓA CHÂN MÀY TRỌN GÓI | J14: 1 | N14: =IFERROR(__xludf.DUMMYFUNCTION("IF(E14="""","""",""0"" & REGEXREPLACE(REGEXREPLACE(E14&"""",""[^0-9]"",""""),""^0+"",""""))"),"0989413672") -> 0989413672
A15: HD028022 | B15: 46026.729 | C15: KH009050 | D15: Tiên Tiên | E15: 0944704036 | F15: Nguyễn Sang | G15: 900000 | H15: SP000453 | I15: (DV) Xóa lần 01 - Chân Mày | J15: 1 | N15: =IFERROR(__xludf.DUMMYFUNCTION("IF(E15="""","""",""0"" & REGEXREPLACE(REGEXREPLACE(E15&"""",""[^0-9]"",""""),""^0+"",""""))"),"0944704036") -> 0944704036
A16: HD028023 | B16: 46026.732 | C16: KH009043 | D16: Evan - Ngọc | E16: 0896146217 | F16: Nguyên Ngọc | G16: 11300000 | H16: SP028167 | I16: (DV) Tạo sợi tả thực [NAM] - DIAMOND | J16: 1 | N16: =IFERROR(__xludf.DUMMYFUNCTION("IF(E16="""","""",""0"" & REGEXREPLACE(REGEXREPLACE(E16&"""",""[^0-9]"",""""),""^0+"",""""))"),"0896146217") -> 0896146217
A17: HD028033 | B17: 46027.557 | C17: KH009054 | D17: Chị Trúc | E17: 0783316640 | F17: Nguyễn Sang | G17: 1490000 | H17: SP002859 | I17: (DV) Công nghệ CO2 Fractional - Tách thâm | J17: 1 | N17: =IFERROR(__xludf.DUMMYFUNCTION("IF(E17="""","""",""0"" & REGEXREPLACE(REGEXREPLACE(E17&"""",""[^0-9]"",""""),""^0+"",""""))"),"0783316640") -> 0783316640
A18: HD028035 | B18: 46027.709 | C18: KH009056 | D18: Tú Lan | E18: 0906528838 | F18: Nguyễn Sang | G18: 900000 | H18: SP000558 | I18: (DV) GÓI TIẾT KIỆM - XÓA CHÂN MÀY TRỌN GÓI | J18: 1 | N18: =IFERROR(__xludf.DUMMYFUNCTION("IF(E18="""","""",""0"" & REGEXREPLACE(REGEXREPLACE(E18&"""",""[^0-9]"",""""),""^0+"",""""))"),"0906528838") -> 0906528838
A19: HD028036 | B19: 46027.749 | C19: KH008276 | D19: Thanh Hồng | E19: 0932781732 | F19: Khánh Linh | G19: 3390000 | H19: SP000190 | I19: (DV) Tạo sợi tả thực (NỮ) - GOLD | J19: 1 | N19: =IFERROR(__xludf.DUMMYFUNCTION("IF(E19="""","""",""0"" & REGEXREPLACE(REGEXREPLACE(E19&"""",""[^0-9]"",""""),""^0+"",""""))"),"0932781732") -> 0932781732
